Workbook

Sheet R001
A1: 风险编号riskid | B1: R001
A2: 风险名称riskname | B2: 虚构营业收入
A3: 风险类型Risk_Category | B3: 收入舞弊（所属的大类）
A4: 定义解释Definition | B4: 虚构营业收入，是指企业在无真实商品交付或服务提供的情况下，通过虚构客户与供应商、伪造销售合同及出库 / 发运 / 验收单据、虚开发票等手段确认销售收入，并常以体外资金循环伪造回款或将虚增收入虚挂应收账款，从而虚增营业收入和利润的交易造假类收入舞弊行为。
A5: 信号编号Signal ID | B5: R001-S01 | C5: R001-S02 | D5: R001-S03 | E5: R001-S04 | F5: R001-S05 | G5: R001-S06 | H5: R001-S07 | I5: R001-S08 | J5: R001-S09
A6: 信号名称Signal_Name | B6: 收入现金流背离 | C6: 应收账款异常膨胀 | D6: 毛利率异常偏高 | E6: 收入增长异常 | F6: 存货与营收背离 | G6: 应计利润异常 | H6: 客户与交易结构异常 | I6: 期末收入确认异常 | J6: 人均产值与薪酬背离
A7: 信号类型Signal_Type | B7: 定量 | C7: 定量 | D7: 定量 | E7: 定量 | F7: 定量 | G7: 定量 | H7: 定量 | I7: 定量+定性 | J7: 定量
A8: 公式Formula | B8: 1. 净现比 = 经营活动产生的现金流量净额 / 净利润 | C8: 应收账款同比增长率 = (期末应收账款余额 - 上年期末应收账款余额) / 上年期末应收账款余额 × 100% | D8: 本期销售毛利率 = (本期营业收入 - 本期营业成本) / 本期营业收入 × 100% | E8: 营业收入同比增长率 = (本期营业收入 - 上期营业收入) / 上期营业收入 × 100% | F8: 平均存货余额 = (期初存货余额 + 期末存货余额) / 2 | G8: 平均总资产 = (期初资产总计 + 期末资产总计) / 2 | H8: 前五大客户销售额合计 = 第一大客户销售额 + 第二大客户销售额 + 第三大客户销售额 + 第四大客户销售额 + 第五大客户销售额 | I8: Q4 营业收入 = 本年度营业收入 - 本年度前三季度营业收入 | J8: 人均产值 = 营业收入 / 期末员工人数
B9: 2. 收现比 = 销售商品、提供劳务收到的现金 / 营业收入 | C9: 营业收入同比增长率 = (本期营业收入 - 上期营业收入) / 上期营业收入 × 100% | D9: 上期销售毛利率 = (上期营业收入 - 上期营业成本) / 上期营业收入 × 100% | E9: 行业平均营业收入增长率 = 同行业可比公司营业收入同比增长率的中位数 | F9: 存货周转率 = 营业成本 / 平均存货余额 | G9: TATA = (净利润 - 经营活动产生的现金流量净额) / 平均总资产 × 100% | H9: CR5 = 前五大客户销售额合计 / 营业收入 × 100% | I9: Q4 收入占比 = Q4 营业收入 / 本年度营业收入 × 100% | J9: 人均薪酬 = 支付给职工以及为职工支付的现金 / 期末员工人数
B10: 3. 营收现金含量 = 经营活动现金流入小计 / 营业收入 | C10: 应收账款增速差 = 应收账款同比增长率 - 营业收入同比增长率 | D10: 毛利率同比变动 = 本期销售毛利率 - 上期销售毛利率 | E10: 营收增长行业偏离 = 公司营业收入同比增长率 - 行业平均营业收入增长率 | F10: 存货周转天数 = 365 / 存货周转率 | G10: 本期营运资本 = 本期流动资产合计 - 本期流动负债合计 | H10: CR1 = 第一大客户销售额 / 营业收入 × 100% | I10: Q3 营业收入 = 本年度前三季度营业收入 - 本年度上半年营业收入 | J10: 人均产值行业倍数 = 公司人均产值 / 行业人均产值
C11: 应收账款营收比 = 期末应收账款余额 / 营业收入 × 100% | D11: 毛利率行业偏离度 = 公司本期销售毛利率 - 行业平均销售毛利率 | E11: SGI = 本期营业收入 / 上期营业收入 | F11: 存货同比增长率 = (期末存货余额 - 上年期末存货余额) / 上年期末存货余额 × 100% | G11: 上期营运资本 = 上期流动资产合计 - 上期流动负债合计 | H11: 新增客户销售额 = 本年度前五大客户中、上一年度前五大客户名单未出现的客户的销售额合计 | I11: Q4 收入环比增速 = (Q4 营业收入 - Q3 营业收入) / Q3 营业收入 × 100% | J11: 人均薪酬行业倍数 = 公司人均薪酬 / 行业人均薪酬
C12: 平均应收账款余额 = (期初应收账款余额 + 期末应收账款余额) / 2 | D12: GMI = 上期销售毛利率 / 本期销售毛利率 | E12: 营业收入三年 CAGR = (本期营业收入 / 三年前营业收入)^(1/3) - 1 | F12: 营业成本同比增长率 = (本期营业成本 - 上期营业成本) / 上期营业成本 × 100% | G12: 营运资本增加额 = 本期营运资本 - 上期营运资本 | H12: 新增客户销售额占比 = 新增客户销售额 / 营业收入 × 100% | I12: 次年 Q1 收入回落率 = (次年 Q1 营业收入 - 当年 Q4 营业收入) / 当年 Q4 营业收入 × 100% | J12: 背离指数 = 人均产值行业倍数 / 人均薪酬行业倍数
C13: 应收账款周转率 = 营业收入 / 平均应收账款余额 | D13: 单季销售毛利率 = (单季营业收入 - 单季营业成本) / 单季营业收入 × 100% | E13: 净利润同比增长率 = (本期净利润 - 上期净利润) / 上期净利润 × 100% | F13: 存货增速差 = 存货同比增长率 - 营业成本同比增长率 | G13: 营运资本应计率 = 营运资本增加额 / 平均总资产 × 100% | H13: 关联方销售占比 = 关联方销售商品 / 提供劳务金额 / 营业收入 × 100% | I13: 历史 Q4 收入占比均值 = (前年 Q4 收入占比 + 大前年 Q4 收入占比 + 大大前年 Q4 收入占比) / 3 | J13: 人均产值同比增长率 = (本期人均产值 - 上期人均产值) / 上期人均产值 × 100%
C14: 应收账款周转天数 = 365 / 应收账款周转率 | D14: Q4 毛利率环比变动 = Q4 销售毛利率 - Q3 销售毛利率 | E14: 营收净利增速差 = 营业收入同比增长率 - 净利润同比增长率 | F14: 存货营收比 = 期末存货余额 / 营业收入 × 100% | G14: 应计利润占比 = (净利润 - 经营活动产生的现金流量净额) / 净利润 × 100% | H14: 客户供应商重叠数 = 同时出现在本年度前五大客户名单和前五大供应商名单中的主体数量 | I14: Q4 收入占比偏离度 = 当年 Q4 收入占比 - 历史 Q4 收入占比均值 | J14: 员工人数同比增长率 = (本期期末员工人数 - 上期期末员工人数) / 上期期末员工人数 × 100%
C15: DSRI = (期末应收账款余额 t / 营业收入 t) / (期末应收账款余额 t-1 / 营业收入 t-1) | F15: 存货周转率同比变动 = 本期存货周转率 - 上期存货周转率
A19: 数据来源Data_Source | B19: 利润表 +现金流量表 | C19: 资产负债表 + 利润表 | D19: 利润表 + 行业可比数据（Wind / 同花顺 / 行业协会） | E19: 利润表 + 行业可比数据 | F19: 资产负债表 + 利润表 | G19: 资产负债表 + 利润表 + 现金流量表 | H19: 年报附注（前五大客户、前五大供应商、关联交易）+ 利润表 + 工商信息（企查查 / 天眼查） | I19: 年度报告 + 季度报告（一季报、半年报、三季报） | J19: 利润表 + 现金流量表 + 年报（员工情况章节）+ 行业可比数据
A20: 阈值Threshold | B20: 净现比：高风险：连续 2 年 <0.5 或任意一年为负，关注：0.5~1，良好：>1 | C20: 应收账款同比增长率：中间变量，不单独判断，参考 > 50% 需警惕 | D20: 本期销售毛利率：中间变量，需结合行业对标判断 | E20: 营业收入同比增长率：中间变量，不单独判断 | F20: 平均存货余额：中间变量，不单独判断 | G20: 平均总资产：中间变量，不单独判断 | H20: 前五大客户销售额合计：中间变量，不单独判断 | I20: Q4 营业收入：中间变量，不单独判断 | J20: 人均产值：中间变量，不单独判断
B21: 收现比：高风险：<1 且连续 2 年下降，关注：<1 但稳定，正常：≥1 | C21: 营业收入同比增长率：中间变量，不单独判断 | D21: 上期销售毛利率：中间变量，不单独判断 | E21: 行业平均营业收入增长率：中间变量（外部数据），不单独判断 | F21: 存货周转率：高风险：连续 2 年下降且累计降幅 > 20%，关注：单年下降 10%~20% | G21: TATA：高风险：连续 2 年 > 10%，关注：>5% 且连续上升，正常：<5% | H21: CR5：关注：>70% 且客户集中度持续上升 | I21: Q4 收入占比：高风险：>40%，关注：30%~40%，正常：约 25% | J21: 人均薪酬：中间变量，不单独判断
B22: 营收现金含量：高风险：连续 2 年 < 0.8，关注：0.8~1，良好：>1 | C22: 应收账款增速差：高风险：>30 个百分点，关注：10~30 个百分点，正常：<10 个百分点 | D22: 毛利率同比变动：高风险：同比上升 > 5 个百分点且无合理商业解释 | E22: 营收增长行业偏离：高风险：公司增速 > 行业均值 2 倍且收入结构未变，关注：1.5~2 倍 | F22: 存货周转天数：高风险：连续 2 年上升且累计增加 > 30 天 | G22: 本期营运资本：中间变量，不单独判断 | H22: CR1：高风险：>30% 且该客户为当年新增主体，关注：>30% 但为长期稳定客户 | I22: Q3 营业收入：中间变量，不单独判断 | J22: 人均产值行业倍数：中间变量，不单独判断
C23: 应收账款营收比：高风险：>30% 且连续 2 年上升，关注：20%~30%，正常：<20%（需结合行业） | D23: 毛利率行业偏离度：高风险：>10 个百分点且无合理解释，关注：5~10 个百分点 | E23: SGI：高风险：>1.6，关注：1.3~1.6，正常：<1.3 | F23: 存货同比增长率：中间变量，不单独判断 | G23: 上期营运资本：中间变量，不单独判断 | H23: 新增客户销售额：中间变量，不单独判断 | I23: Q4 收入环比增速：高风险：>50% 且无合理季节性解释，关注：30%~50% | J23: 人均薪酬行业倍数：中间变量，不单独判断
C24: 平均应收账款余额：中间变量，不单独判断 | D24: GMI：关注：>1.2（毛利率恶化有操纵动机），正常：<1.2 | E24: 营业收入三年 CAGR：关注：>30% 且最近一年增速突然加速 | F24: 营业成本同比增长率：中间变量，不单独判断 | G24: 营运资本增加额：中间变量，不单独判断 | H24: 新增客户销售额占比：高风险：>20%，关注：10%~20% | I24: 次年 Q1 收入回落率：高风险：回落 > 30%，关注：15%~30% | J24: 背离指数：高风险：>2，关注：1.5~2
C25: 应收账款周转率：高风险：同比下降 > 20% 且低于行业均值，关注：下降 10%~20% | D25: 单季销售毛利率：中间变量，不单独判断 | E25: 净利润同比增长率：中间变量，不单独判断 | F25: 存货增速差：高风险：>20 个百分点，关注：10~20 个百分点 | G25: 营运资本应计率：高风险：连续 2 年 > 8%，关注：5%~8% | H25: 关联方销售占比：高风险：>20% 且交易定价不公允，关注：10%~20% | I25: 历史 Q4 收入占比均值：中间变量，不单独判断 | J25: 人均产值同比增长率：中间变量，与员工人数增长率联合判断
C26: 应收账款周转天数：高风险：同比增加 > 30 天且高于行业均值 | D26: Q4 毛利率环比变动：高风险：突增 > 5 个百分点（期末突击确认高毛利收入嫌疑） | E26: 营收净利增速差：关注：>20 个百分点（营收远高于利润增长） | F26: 存货营收比：关注：连续 2 年上升且高于行业均值 | G26: 应计利润占比：高风险：>50%，关注：30%~50% | H26: 客户供应商重叠数：高风险：≥1 | I26: Q4 收入占比偏离度：高风险：>10 个百分点，关注：5~10 个百分点 | J26: 员工人数同比增长率：联合判断：人均产值同比增长 > 30% 但员工人数增长 < 5% 为高风险，人均产值增长 20%~30% 且员工增长 < 5% 为关注
C27: DSRI：高风险：>1.5，关注：1.2~1.5，正常：<1.2 | F27: 存货周转率同比变动：高风险：同比下降 > 20%
A31: RAG_Keywords | B31: 营业收入 / 主营业务收入 / 其他业务收入 / 营业总收入 / 营收；经营活动产生的现金流量净额 / 经营活动现金流净额 / 经营现金流净额 / 经营活动产生的现金流量；销售商品、提供劳务收到的现金 / 销售商品提供劳务收到的现金 / 销售商品收到的现金；经营活动现金流入小计 / 经营活动现金流入；净利润 / 归属于母公司所有者的净利润 / 归母净利润 / 扣除非经常性损益后的净利润；现金流量表 / 现金及现金等价物净增加额；销售回款 / 现金回款 / 回款情况 / 回款率；收现比 / 净现比 / 利润含金量 / 现金流与净利润背离 / 经营现金流为负 / 增收不增现 | C31: 应收账款 / 应收账款及应收票据 / 应收票据 / 应收款项融资 / 应收账款融资；应收账款余额 / 应收账款账面价值 / 应收账款账面余额 / 应收账款净额；坏账准备 / 应收账款坏账准备 / 信用减值损失 / 坏账损失；应收账款周转率 / 应收账款周转天数 / 应收账款回收期 / 平均收现期；账龄 / 账龄分析 / 账龄组合 / 逾期应收账款 / 逾期未收回；前五大应收账款 / 应收账款前五名 / 应收账款欠款方；信用政策 / 赊销政策 / 结算方式 / 信用期；应收账款占比 / 应收账款增长 / 应收账款大幅增加 / 应收账款异常；应收股利 / 应收利息 / 其他应收款 / 长期应收款；保理 / 应收账款保理 / 应收账款质押 / 应收账款证券化 | D31: 毛利率 / 销售毛利率 / 综合毛利率 / 主营业务毛利率 / 分产品毛利率 / 分行业毛利率 / 分地区毛利率；营业成本 / 主营业务成本 / 其他业务成本 / 营业总成本；营业收入 / 主营业务收入；毛利率变动 / 毛利率波动 / 毛利率提升 / 毛利率下降 / 毛利率同比；成本构成 / 成本结构 / 原材料成本 / 直接人工 / 制造费用；产品结构 / 产品升级 / 高毛利产品 / 低毛利产品 / 产品结构优化；同行业对比 / 行业平均毛利率 / 可比公司毛利率 / 行业均值；核心竞争力 / 技术壁垒 / 品牌溢价 / 定价权 / 规模效应；单位成本 / 单位售价 / 量价分析；存货跌价 / 成本结转 / 发出商品 | E31: 营业收入 / 主营业务收入 / 营业总收入 / 营收；营业收入增长率 / 营收增速 / 收入增长 / 同比增长 / 同比增幅 / 同比变动；主营业务增长率 / 收入增速 / 营收同比；行业增长 / 行业平均增长率 / 市场规模 / 行业增速 / 市场份额；收入结构 / 产品结构 / 地区结构 / 客户结构 / 收入构成；新增业务 / 新产品 / 新市场 / 新领域 / 业务拓展；业绩增长 / 业绩驱动 / 增长驱动因素 / 增长原因 / 增长可持续性；三年复合增长率 / CAGR / 复合增长率；净利润增长率 / 利润增速 / 归母净利润增速；营收与利润背离 / 增收不增利 / 利润增速低于营收增速；季度营收 / 单季收入 / 分季度财务数据 | F31: 存货 / 存货余额 / 存货账面价值 / 存货账面余额 / 存货净额；存货跌价准备 / 存货跌价损失 / 资产减值损失 / 存货减值；存货周转率 / 存货周转天数 / 库存周转 / 库存周转天数；原材料 / 在产品 / 库存商品 / 发出商品 / 委托加工物资 / 周转材料 / 低值易耗品；存货结构 / 存货构成 / 存货分类；存货增长 / 库存增加 / 备货 / 加大备货 / 原材料储备；营业成本 / 主营业务成本 / 营业成本同比；库龄 / 库龄分析 / 滞销 / 积压 / 滞销库存 / 库存积压；存货盘点 / 实物流转 / 盘点差异 / 账实不符；产销率 / 产能利用率 / 产量 / 销量 / 库存量；期末存货 / 年末存货 / 存货大幅增加 | G31: 净利润 / 经营活动产生的现金流量净额 / 经营现金流净额；应计利润 / 应计项 / 权责发生制 / 收付实现制；流动资产 / 流动负债 / 营运资本 / 营运资金 / 营运资本增加；资产总计 / 总资产 / 平均总资产 / 资产总额；非经常性损益 / 非经常性损益项目 / 非经常性损益明细；资产减值损失 / 信用减值损失 / 减值准备 / 减值计提；公允价值变动收益 / 投资收益 / 资产处置收益 / 其他收益；固定资产折旧 / 累计折旧 / 无形资产摊销 / 长期待摊费用摊销 / 使用权资产折旧；经营性应收项目 / 经营性应付项目 / 经营性应收项目的减少 / 经营性应付项目的增加；递延所得税资产 / 递延所得税负债 / 递延所得税；将净利润调节为经营活动现金流量 / 现金流量表补充资料 / 间接法 | H31: 前五大客户 / 前五名客户 / 前五大客户销售额 / 前五大客户销售占比 / 前五名客户销售额；第一大客户 / 最大客户 / 主要客户 / 重要客户 / 核心客户；客户集中度 / 客户依赖 / 重大客户依赖 / 客户集中风险；新增客户 / 新增大客户 / 新开发客户 / 新增重要客户 / 新增前五大客户；关联方 / 关联交易 / 关联销售 / 关联方销售 / 向关联方销售商品 / 关联方交易；日常关联交易 / 偶发性关联交易 / 日常经营相关的关联交易；关联方资金占用 / 关联往来 / 关联方应收应付款项；前五大供应商 / 前五名供应商 / 前五大供应商采购额 / 供应商集中度 / 主要供应商；客户与供应商重叠 / 同一客户供应商 / 既是客户又是供应商 / 循环贸易 / 循环交易 / 资金循环；无商业实质 / 贸易性收入 / 转口贸易 / 供应链贸易 / 大宗商品贸易 / 贸易业务；客户背景 / 客户成立时间 / 客户注册资本 / 客户工商信息 / 穿透核查；销售合同 / 订单 / 框架协议 / 长期合同 / 重大合同 | I31: 第四季度 / Q4 / 四季度 / 年末 / 期末 / 年底 / 年末突击 / 年末冲量；第一季度 / Q1 / 一季度 / 次年一季度 / 期后；季度报告 / 一季报 / 半年报 / 三季报 / 年度报告 / 分季度财务指标；收入确认 / 收入确认政策 / 收入确认时点 / 收入确认方法 / 收入确认条件 / 收入确认原则；履约义务 / 履约进度 / 合同履约成本 / 合同资产 / 合同负债 / 合同结算；时段法 / 时点法 / 完工百分比法 / 投入法 / 产出法 / 履约进度确认方法；跨期确认 / 提前确认 / 延后确认 / 截止性测试 / 收入截止 / 收入跨期 / 跨期收入；期末突击确认 / 年末集中确认 / 年末大额确认 / 期末收入异常；期后退回 / 销售退回 / 期后销售退回 / 退货率 / 退换货；发货 / 出库 / 签收 / 验收 / 交付 / 到货 / 安装调试 / 控制权转移；季节性 / 旺季 / 淡季 / 季节性波动 / 季节性因素 / 行业季节性；新收入准则 / 收入准则变更 / 会计政策变更 / 收入准则衔接 | J31: 员工人数 / 在职员工数量 / 员工总数 / 员工数量合计 / 在职员工的数量合计 / 母公司及主要子公司在职员工总数；劳务派遣 / 劳务外包 / 外包人员 / 人力资源外包 / 劳务派遣人员 / 外包用工；员工结构 / 员工构成 / 专业构成 / 教育程度 / 年龄分布 / 学历结构 / 岗位结构；人均产值 / 人均创收 / 人均营业收入 / 人均销售 / 人均产出；人均薪酬 / 人均工资 / 职工薪酬 / 人均职工薪酬 / 平均薪酬；支付给职工以及为职工支付的现金 / 支付给职工的现金 / 支付给职工以及为职工支付；应付职工薪酬 / 应付职工薪酬期末余额 / 应付职工薪酬期初余额 / 短期薪酬 / 离职后福利；工资 / 奖金 / 津贴 / 补贴 / 社保 / 住房公积金 / 福利费 / 工会经费 / 职工教育经费；员工人数变动 / 人员增减 / 裁员 / 扩招 / 人员优化 / 人员变动；自动化 / 智能制造 / 机器换人 / 人均效率 / 劳动生产率 / 生产效率；同行业人均薪酬 / 行业平均薪酬 / 可比公司人均薪酬 / 薪酬水平；核心技术人员 / 研发人员 / 销售人员 / 生产人员 / 技术人员数量；员工持股 / 股权激励 / 股份支付 / 薪酬政策 / 绩效考核
A32: Evidence_Required

Sheet R002
A1: 风险编号riskid | B1: R001
A2: 风险名称riskname | B2: 提前确认收入（跨期确认）
A3: 风险类型Risk_Category | B3: 收入舞弊（所属的大类）
A4: 定义解释Definition | B4: 企业在收入确认条件尚未满足时（商品未发出、客户未验收、服务未提供完毕），将本应属于后续期间的收入提前至本期确认。常见手段：期末突击开票、未发货即确认、完工百分比法高估进度、预收账款提前转收入、验收确认改发货确认。与虚构收入的区别：交易可能真实存在但确认时点违反准则
A5: 信号编号Signal ID | B5: R002-S01 | C5: R002-S02 | D5: R002-S03 | E5: R002-S04 | F5: R002-S05 | G5: R002-S06 | H5: R002-S07 | I5: R002-S08 | J5: R002-S09
A6: 信号名称Signal_Name | B6: 期末收入确认异常 | C6: 应收账款与收入增速背离 | D6: 存货与营收背离（未发货提前确认） | E6: 合同负债 / 预收账款异常减少 | F6: 经营现金流与收入背离 | G6: 期后销售退回 / 冲销异常 | H6: 收入确认政策激进或频繁变更 | I6: 毛利率期末异常波动 | J6: 应收账款账龄与回收异常
A7: 信号类型Signal_Type | B7: 定量 | C7: 定量 | D7: 定量 | E7: 定量 | F7: 定量 | G7: 定量 | H7: 定性（含量化辅助指标） | I7: 定量 | J7: 定量
A8: 公式Formula | B8: Q4 收入占比 = 第四季度营业收入 / 全年营业收入 × 100% | C8: 应收账款同比增长率 =（期末应收账款余额 - 上年期末应收账款余额）/ 上年期末应收账款余额 × 100% | D8: 存货同比增长率 =（期末存货余额 - 上年期末存货余额）/ 上年期末存货余额 × 100% | E8: 合同负债同比增长率 =（期末合同负债余额 - 上年期末合同负债余额）/ 上年期末合同负债余额 × 100% | F8: 净现比 = 经营活动产生的现金流量净额 / 净利润 × 100% | G8: 期后退回率 = 资产负债表日后销售退回金额 / 第四季度营业收入 × 100% | H8: 收入确认政策变更次数 = 近 3 年发生收入确认会计政策变更的次数（直接计数） | I8: Q1 毛利率 =（Q1 营业收入 - Q1 营业成本）/ Q1 营业收入 × 100% | J8: 1 年以上应收账款余额 = 1-2 年应收账款 + 2-3 年应收账款 + 3 年以上应收账款
B9: Q4 环比增速 =（第四季度营业收入 - 第三季度营业收入）/ 第三季度营业收入 × 100% | C9: 营业收入同比增长率 =（本期营业收入 - 上期营业收入）/ 上期营业收入 × 100% | D9: 存货增速差 = 存货同比增长率 - 营业收入同比增长率 | E9: 合同负债增速差 = 合同负债同比增长率 - 营业收入同比增长率 | F9: 销售收现比 = 销售商品提供劳务收到的现金 / 营业收入 × 100% | G9: 本期销售退回率 = 本期销售退回金额 / 本期营业收入 × 100% | H9: 时段法收入占比 = 按时段法确认的营业收入 / 全年营业收入 × 100% | I9: Q2 毛利率 =（Q2 营业收入 - Q2 营业成本）/ Q2 营业收入 × 100% | J9: 1 年以上应收账款占比 = 1 年以上应收账款余额 / 应收账款账面余额合计 × 100%
B10: Q4-Q1 收入差值率 =（第四季度营业收入 - 第一季度营业收入）/ 第一季度营业收入 × 100% | C10: 应收账款增速差 = 应收账款同比增长率 - 营业收入同比增长率 | D10: 存货营收比变动 =（期末存货余额 t / 营业收入 t - 期末存货余额 t-1 / 营业收入 t-1）× 100% | E10: 合同负债营收比变动 =（期末合同负债余额 t / 营业收入 t - 期末合同负债余额 t-1 / 营业收入 t-1）× 100% | F10: 经营现金流营收比 = 经营活动产生的现金流量净额 / 营业收入 × 100% | G10: 上期销售退回率 = 上期销售退回金额 / 上期营业收入 × 100% | H10: 发货确认收入占比 = 按发货确认收入的业务线收入 / 全年营业收入 × 100% | I10: Q3 毛利率 =（Q3 营业收入 - Q3 营业成本）/ Q3 营业收入 × 100% | J10: 1 年以上占比变动 = 1 年以上应收账款占比 t - 1 年以上应收账款占比 t-1
B11: 下半年收入占比 =（第三季度营业收入 + 第四季度营业收入）/ 全年营业收入 × 100% | C11: 应收账款营收比 = 期末应收账款余额 / 营业收入 × 100% | D11: 发出商品占存货比 = 发出商品期末余额 / 存货期末账面余额 × 100% | E11: 预收账款变动率 =（期末预收账款余额 t - 期末预收账款余额 t-1）/ 期末预收账款余额 t-1 × 100% | F11: 销售收现比变动 =（销售商品提供劳务收到的现金 t / 营业收入 t - 销售商品提供劳务收到的现金 t-1 / 营业收入 t-1）× 100% | G11: 销售退回率变动 = 本期销售退回率 - 上期销售退回率 | H11: 收入确认时点激进度评分 = Σ（各业务线收入占比 × 确认时点得分），发货确认 = 3，签收确认 = 2，验收确认 = 1，收款确认 = 0 | I11: Q4 毛利率 =（Q4 营业收入 - Q4 营业成本）/ Q4 营业收入 × 100% | J11: 平均应收账款余额 =（期初应收账款余额 + 期末应收账款余额）/ 2
B12: 12 月收入集中度 = 12 月营业收入 / 第四季度营业收入 × 100% | C12: 应收账款营收比变动 =（期末应收账款余额 t / 营业收入 t - 期末应收账款余额 t-1 / 营业收入 t-1）× 100% | D12: 发出商品增速 =（发出商品期末余额 t - 发出商品期末余额 t-1）/ 发出商品期末余额 t-1 × 100% | E12: 递延收入合计 = 期末合同负债余额 + 期末预收账款余额 | G12: 营业收入冲销额占比 = 本期对上期营业收入的冲销调整额 / 上期营业收入 × 100% | H12: 总额法收入占比 = 按总额法确认的营业收入 / 全年营业收入 × 100% | I12: 前三季度平均毛利率 =（Q1 毛利率 + Q2 毛利率 + Q3 毛利率）/ 3 | J12: DSO 应收账款周转天数 = 平均应收账款余额 / 营业收入 × 365
C13: 平均应收账款余额 =（期初应收账款余额 + 期末应收账款余额）/ 2 | D13: 平均存货余额 =（期初存货余额 + 期末存货余额）/ 2 | E13: 递延收入合计变动率 =（递延收入合计 t - 递延收入合计 t-1）/ 递延收入合计 t-1 × 100% | I13: Q4 毛利率偏离度 = Q4 毛利率 - 前三季度平均毛利率 | J13: 坏账准备计提率 = 坏账准备期末余额 / 应收账款账面余额合计 × 100%
C14: 应收账款周转率 = 营业收入 / 平均应收账款余额 | D14: 存货周转率 = 营业成本 / 平均存货余额 | I14: 年均毛利率 =（Q1 毛利率 + Q2 毛利率 + Q3 毛利率 + Q4 毛利率）/ 4 | J14: 坏账准备计提率变动 = 坏账准备计提率 t - 坏账准备计提率 t-1
C15: 应收账款周转天数 = 365 / 应收账款周转率 | D15: 存货周转天数 = 365 / 存货周转率 | E15: ## 5. 经营现金流与收入背离 | I15: 毛利率季度波动率 = √[（Q1 毛利率 - 年均毛利率）² +（Q2 毛利率 - 年均毛利率）² +（Q3 毛利率 - 年均毛利率）² +（Q4 毛利率 - 年均毛利率）²] / 4 | J15: 应收账款保理比例 =（应收账款保理金额 + 应收账款贴现金额 + 应收账款证券化金额）/ 应收账款期末账面余额 × 100%
C16: DSO 变动 = 应收账款周转天数 t - 应收账款周转天数 t-1 | D16: 存货周转天数变动 = 存货周转天数 t - 存货周转天数 t-1 | I16: 上半年毛利率 =（Q1 营业收入 + Q2 营业收入 - Q1 营业成本 - Q2 营业成本）/（Q1 营业收入 + Q2 营业收入）× 100%
C17: DSRI =（期末应收账款余额 t / 营业收入 t）/（期末应收账款余额 t-1 / 营业收入 t-1） | I17: 下半年毛利率 =（Q3 营业收入 + Q4 营业收入 - Q3 营业成本 - Q4 营业成本）/（Q3 营业收入 + Q4 营业收入）× 100%
I18: 下半年 - 上半年毛利率差值 = 下半年毛利率 - 上半年毛利率
I19: Q4 毛利率同比变动 = Q4 毛利率 t - Q4 毛利率 t-1
A20: 数据来源Data_Source | B20: 利润表（分季度主要财务指标） | C20: 资产负债表 + 利润表 | D20: 资产负债表 + 利润表 | E20: 资产负债表 + 利润表 | F20: 利润表 + 现金流量表 | G20: 利润表（分季度）+ 年报附注（资产负债表日后事项、会计差错更正） | H20: 年报附注（重要会计政策变更、收入确认政策、收入分解信息） | I20: 利润表（分季度营业收入、分季度营业成本） | J20: 资产负债表 + 利润表 + 年报附注（应收账款账龄分析、坏账准备、应收账款转移）
A21: 阈值Threshold | B21: Q4 收入占比：高风险：>40%，关注：35%~40%，正常：<35% | C21: 应收账款同比增长率：中间变量，不单独判断 | D21: 存货同比增长率：中间变量，不单独判断 | E21: 合同负债同比增长率：中间变量，不单独判断 | F21: 净现比：高风险：连续 2 年 <0.5 或任意一年为负，关注：0.5~1，良好：>1 | G21: 期后退回率：高风险：>5%，关注：3%~5%，正常：<3% | H21: 收入确认政策变更次数：高风险：近 3 年≥2 次，关注：近 3 年 = 1 次，正常：0 次 | I21: Q1 毛利率：中间变量，不单独判断 | J21: 1 年以上应收账款余额：中间变量，不单独判断
B22: Q4 环比增速：高风险：>50%，关注：30%~50%，正常：<30% | C22: 营业收入同比增长率：中间变量，不单独判断 | D22: 存货增速差：高风险：>30 个百分点（存货增速远超营收），关注：15~30 个百分点，正常：<15 个百分点 | E22: 合同负债增速差：高风险：<-30 个百分点（合同负债增速远低于营收），关注：-20~-30 个百分点，正常：>-20 个百分点 | F22: 销售收现比：高风险：<1 且连续 2 年下降，关注：<1 但稳定，正常：≥1 | G22: 本期销售退回率：中间变量，不单独判断 | H22: 时段法收入占比：高风险：>50% 且完工进度依赖管理层估计，关注：30%~50%，正常：<30% | I22: Q2 毛利率：中间变量，不单独判断 | J22: 1 年以上应收账款占比：高风险：>20%，关注：15%~20%，正常：<15%
B23: Q4-Q1 收入差值率：高风险：>100%，关注：50%~100%，正常：<50% | C23: 应收账款增速差：高风险：>30 个百分点，关注：10~30 个百分点，正常：<10 个百分点 | D23: 存货营收比变动：高风险：同比上升 > 5 个百分点，关注：3~5 个百分点，正常：<3 个百分点 | E23: 合同负债营收比变动：高风险：同比下降 > 5 个百分点，关注：下降 2~5 个百分点，正常：<2 个百分点 | F23: 经营现金流营收比：高风险：连续 2 年 < 0 或为负，关注：0~5%，良好：>5% | G23: 上期销售退回率：中间变量，不单独判断 | H23: 发货确认收入占比：高风险：>20%，关注：10%~20%，正常：<10% | I23: Q3 毛利率：中间变量，不单独判断 | J23: 1 年以上占比变动：高风险：同比上升 > 5 个百分点，关注：上升 3~5 个百分点，正常：<3 个百分点
B24: 下半年收入占比：高风险：>60%，关注：55%~60%，正常：<55% | C24: 应收账款营收比：高风险：>30% 且连续 2 年上升，关注：20%~30%，正常：<20%（需结合行业） | D24: 发出商品占存货比：高风险：>30% 或同比上升 > 10 个百分点，关注：20%~30%，正常：<20% | E24: 预收账款变动率：高风险：同比下降 > 30% 且同期营收增长，关注：下降 20%~30%，正常：<20% | F24: 销售收现比变动：高风险：同比下降 > 10 个百分点，关注：下降 5~10 个百分点，正常：<5 个百分点 | G24: 销售退回率变动：高风险：同比上升 > 5 个百分点，关注：上升 2~5 个百分点，正常：<2 个百分点 | H24: 收入确认时点激进度评分：高风险：>2.0，关注：1.5~2.0，正常：<1.5 | I24: Q4 毛利率：中间变量，不单独判断 | J24: 平均应收账款余额：中间变量，不单独判断
B25: 12 月收入集中度：高风险：>50%，关注：40%~50%，正常：<40%（均匀分布约 33%） | C25: 应收账款营收比变动：高风险：同比上升 > 5 个百分点，关注：3~5 个百分点，正常：<3 个百分点 | D25: 发出商品增速：高风险：>50% 且显著高于营收增速，关注：30%~50%，正常：<30% | E25: 递延收入合计：中间变量，不单独判断 | G25: 营业收入冲销额占比：高风险：>3% 或存在营业收入追溯调减，关注：1%~3%，正常：<1% | H25: 总额法收入占比：高风险：近 3 年从净额法改为总额法，或贸易类业务 > 70%，关注：50%~70%，正常：<50% | I25: 前三季度平均毛利率：中间变量，不单独判断 | J25: DSO 应收账款周转天数：高风险：>120 天或同比增幅 > 20%，关注：90~120 天，正常：<90 天
C26: 平均应收账款余额：中间变量，不单独判断 | D26: 平均存货余额：中间变量，不单独判断 | E26: 递延收入合计变动率：高风险：同比下降 > 25% 且同期营收正增长，关注：下降 15%~25%，正常：<15% | I26: Q4 毛利率偏离度：高风险：偏离前三季均值 > 5 个百分点（无论偏高或偏低），关注：3~5 个百分点，正常：<3 个百分点 | J26: 坏账准备计提率：中间变量，不单独判断
C27: 应收账款周转率：高风险：同比下降 > 20% 且低于行业均值，关注：下降 10%~20%，正常：≥行业均值 | D27: 存货周转率：高风险：同比下降 > 20% 且低于行业均值，关注：下降 10%~20%，正常：≥行业均值 | I27: 年均毛利率：中间变量，不单独判断 | J27: 坏账准备计提率变动：高风险：在账龄恶化背景下同比下降 > 3 个百分点，关注：下降 2~3 个百分点，正常：<2 个百分点
C28: 应收账款周转天数：高风险：同比增加 > 30 天且高于行业均值，关注：增加 10~30 天，正常：<10 天 | D28: 存货周转天数：高风险：同比增加 > 30 天，关注：增加 15~30 天，正常：<15 天 | I28: 毛利率季度波动率：高风险：标准差 > 5 个百分点，关注：3~5 个百分点，正常：<3 个百分点 | J28: 应收账款保理比例：高风险：>25% 或附追索权保理，关注：15%~25%，正常：<15%
C29: DSO 变动：高风险：同比增加 > 20 天或增幅 > 20%，关注：增加 10~20 天，正常：<10 天 | D29: 存货周转天数变动：高风险：同比增加 > 30 天，关注：增加 15~30 天，正常：<15 天 | I29: 上半年毛利率：中间变量，不单独判断
C30: DSRI：高风险：>1.5，关注：1.2~1.5，正常：<1.2 | I30: 下半年毛利率：中间变量，不单独判断
I31: 下半年 - 上半年毛利率差值：高风险：绝对值 > 5 个百分点，关注：3~5 个百分点，正常：<3 个百分点
I32: Q4 毛利率同比变动：高风险：绝对值 > 8 个百分点，关注：5~8 个百分点，正常：<5 个百分点
A33: RAG_Keywords | B33: 分季度营业收入、季度营业收入、第一季度营业收入、第二季度营业收入、第三季度营业收入、第四季度营业收入、分季度主要财务指标、营业收入、营业总收入、主营业务收入、其他业务收入、年末、季末、期末、资产负债表日、12 月、十二月、第四季度、季节性波动、周期性、收入确认时点、截止性测试、截止测试、期后事项、突击确认、集中确认、年末冲业绩、收入波动、营收波动、季度波动、下半年收入、上半年收入、半年度报告、季度报告、四季度占比、Q4 占比、期末激增、年末大单、年末集中发货 | C33: 应收账款、应收账款余额、应收账款账面余额、应收账款账面价值、应收账款期末余额、应收账款期初余额、坏账准备、坏账准备计提、信用减值损失、应收账款周转率、应收账款周转天数、DSO、应收账款同比、应收账款增长、应收增速、营业收入同比、营收增长、营收增速、赊销、信用政策、信用期、账期、应收款项、应收票据、其他应收款、应收账款账龄、账龄分析、收入质量、盈利质量、应计利润、应收账款占比、应收营收比、应收账款变动、DSRI、Days Sales in Receivables、平均应收账款余额、应收账款回收、回款周期 | D33: 存货、存货余额、存货账面余额、存货账面价值、存货期末余额、存货期初余额、发出商品、在途物资、库存商品、原材料、委托加工物资、开发成本、开发产品、存货周转率、存货周转天数、存货跌价准备、存货减值、营业成本、主营业务成本、发货、出库、出库单、发货单、物流、运输、货运、承运人、货代、验收、签收、到货、入库、存货盘点、盘存、永续盘存制、合同履约成本、合同资产、控制权转移、风险报酬转移、平均存货余额、存货占比、存货变动、发出商品占比、商品已发出未验收、在途商品 | E33: 合同负债、合同负债余额、合同负债期末余额、合同负债期初余额、合同负债账面价值、预收账款、预收款项、预收款、预收账款余额、递延收入、递延收益、预收款、定金、订金、保证金、预收账款转收入、预收账款结转、合同负债减少、合同负债变动、预收款确认收入、预收款结转收入、新收入准则、收入准则、CAS14、企业会计准则第 14 号、履约义务、履约进度、时段法、时点法、预收款比例、预收款占比、合同负债占比、合同负债同比、预收账款同比、预收账款减少、合同负债结转、预收款释放、预收款消化 | F33: 经营活动产生的现金流量净额、经营现金流、经营性现金流、经营活动现金流量净额、销售商品提供劳务收到的现金、销售收现、现金流量表、经营活动现金流量、净利润、归母净利润、归属于母公司股东的净利润、归属于上市公司股东的净利润、净现比、盈利现金比率、现金含量、收现比、销售收现率、收入现金含量、经营活动现金流入、经营活动现金流出、收到的税费返还、收到其他与经营活动有关的现金、购买商品接受劳务支付的现金、支付给职工以及为职工支付的现金、现金流恶化、经营现金流为负、经营性现金流量净额、现金及现金等价物、经营活动产生的现金流量、销售收现比、收现比率 | G33: 销售退回、退货、退回、退换货、销售折让、折扣、返利、资产负债表日后事项、期后事项、日后事项、期后退回、期后销售退回、资产负债表日后退回、会计差错更正、前期差错更正、追溯重述、追溯调整、营业收入调整、营收冲减、收入冲销、销售退回率、退货率、退换货率、冲回、冲减、冲销、调减、期后回款、期后收款、商品发出后期后退回、货运代理人退回、销售合同撤销、合同解除、合同变更、期后大额退回、年末销售次年退回、营业收入追溯调减、差错更正涉及收入 | H33: 收入确认政策、收入确认会计政策、收入确认方法、会计政策变更、重要会计政策变更、会计估计变更、收入确认时点、收入确认条件、控制权转移、发货确认、发出商品确认、出库确认、验收确认、客户验收、签收确认、到货确认、收款确认、收到款项确认、完工百分比法、完工进度、履约进度、投入法、产出法、时段法、时段确认、一段时间内确认、时点法、时点确认、某一时点确认、总额法、净额法、主要责任人、代理人、新收入准则、CAS14、企业会计准则第 14 号 —— 收入、收入确认政策变更、收入政策调整、风险报酬转移、主要风险和报酬、收入确认原则、收入确认具体原则、商品销售收入、提供劳务收入、让渡资产使用权收入 | I33: 毛利率、销售毛利率、综合毛利率、主营业务毛利率、分季度毛利率、季度毛利率、Q1 毛利率、Q2 毛利率、Q3 毛利率、Q4 毛利率、营业成本、主营业务成本、营业总成本、分季度营业成本、季度营业成本、毛利、毛利额、主营业务毛利、毛利率波动、毛利率变动、毛利率变化、下半年毛利率、上半年毛利率、H1 毛利率、H2 毛利率、产品毛利率、分产品毛利率、分行业毛利率、分地区毛利率、毛利率同比、毛利率环比、第四季度毛利率、年末毛利率、成本结转、成本确认、成本分摊、分季度财务指标、季度毛利、毛利率偏离、毛利率异常、毛利率提升、毛利率下降 | J33: 应收账款账龄、账龄分析、账龄结构、1 年以内、1-2 年、2-3 年、3 年以上、3-4 年、4-5 年、5 年以上、坏账准备、坏账准备计提、坏账准备计提比例、坏账准备计提率、信用减值损失、资产减值损失、应收账款回收、回款、收款、收账、应收账款保理、保理、应收账款贴现、贴现、应收账款证券化、ABS、资产证券化、附追索权保理、无追索权保理、应收账款转移、金融资产转移、终止确认、应收账款周转率、应收账款周转天数、DSO、逾期应收账款、逾期款项、逾期、单项计提坏账准备、组合计提坏账准备、应收账款余额前五名、欠款方前五名、坏账准备转回、坏账准备核销、应收账款账龄组合、预期信用损失、信用风险、应收账款保理融资、应收账款质押
A34: Evidence_Required

Sheet R003
A1: 风险编号riskid | B1: R003
A2: 风险名称riskname | B2: 虚增非经常性损益
A3: 风险类型Risk_Category | B3: 收入舞弊（所属的大类）
A4: 定义解释Definition | B4: 虚增非经常性损益是指企业通过虚构或夸大非经常性损益项目（如政府补助、资产处置收益、债务重组收益、非货币性资产交换收益、公允价值变动损益等），或将日常经营损益包装为非经常性损益，以虚增净利润、实现扭亏为盈或满足再融资/保壳条件。核心特征：净利润为正但扣除非经常性损益后的净利润为负或远低于净利润，非经常性损益占净利润比例极高且不可持续。常见手段：①虚构政府补助或提前确认与资产相关的政府补助；②年末突击处置资产产生大额处置收益；③通过债务豁免、非货币性资产交换产生收益；④将日常经营收入包装为营业外收入；⑤利用公允价值变动和投资收益调节利润。
A5: 信号编号Signal ID | B5: R003-S01 | C5: R003-S02 | D5: R003-S03 | E5: R003-S04 | F5: R003-S05 | G5: R003-S06 | H5: R003-S07 | I5: R003-S08 | J5: R003-S09
A6: 信号名称Signal_Name | B6: 非经常性损益占比异常 | C6: 扣非净利润与净利润背离 | D6: 资产处置收益异常 | E6: 政府补助异常 | F6: 债务重组/非货币性交换收益异常 | G6: 公允价值变动损益异常 | H6: 投资收益异常（非主业） | I6: 营业外收支/其他收益异常 | J6: 非经常性损益持续性/波动性异常
A7: 信号类型Signal_Type | B7: 定量 | C7: 定量 | D7: 定量 | E7: 定量 | F7: 定量 | G7: 定量 | H7: 定量 | I7: 定量 | J7: 定量
A8: 公式Formula | B8: 非经常性损益占净利润比：非经常性损益 / 净利润 × 100% | C8: 净利润与扣非净利润差值：净利润 - 扣除非经常性损益的净利润 | D8: 非流动资产处置损益占净利润比：非流动资产处置损益（包括已计提资产减值准备的冲销部分） / 净利润 × 100% | E8: 政府补助占净利润比：计入当期损益的政府补助 / 净利润 × 100% | F8: 债务重组收益占净利润比：债务重组收益 / 净利润 × 100% | G8: 公允价值变动损益占净利润比：公允价值变动损益 / 净利润 × 100% | H8: 投资收益占净利润比：投资收益 / 净利润 × 100% | I8: 营业外收入占净利润比：营业外收入 / 净利润 × 100% | J8: 非经常性损益年度波动率：近3年非经常性损益的标准差 / 近3年非经常性损益均值的绝对值 × 100%
B9: 非经常性损益占营收比：非经常性损益 / 营业收入 × 100% | C9: 扣非净利润占净利润比：扣除非经常性损益的净利润 / 净利润 × 100% | D9: 非流动资产处置损益占非经常性损益比：非流动资产处置损益 / 非经常性损益合计 × 100% | E9: 政府补助占非经常性损益比：计入当期损益的政府补助 / 非经常性损益合计 × 100% | F9: 非货币性资产交换收益占净利润比：非货币性资产交换产生的收益 / 净利润 × 100% | G9: 公允价值变动损益同比增速：(本期公允价值变动损益 - 上期公允价值变动损益) / |上期公允价值变动损益| × 100% | H9: 投资收益占营业利润比：投资收益 / 营业利润 × 100% | I9: 营业外收入同比增速：(本期营业外收入 - 上期营业外收入) / 上期营业外收入 × 100% | J9: 非经常性损益连续3年占净利润比均值：近3年各年非经常性损益占净利润比的算术平均值
B10: 非经常性损益同比增速：(本期非经常性损益 - 上期非经常性损益) / |上期非经常性损益| × 100% | C10: 净利润为正扣非为负判断：IF(净利润>0 AND 扣非净利润<0, 1, 0) | D10: 资产处置收益同比增速：(本期非流动资产处置损益 - 上期非流动资产处置损益) / |上期非流动资产处置损益| × 100% | E10: 政府补助同比增速：(本期政府补助 - 上期政府补助) / 上期政府补助 × 100% | F10: 债务重组收益同比变动：本期债务重组收益 - 上期债务重组收益 | G10: 公允价值变动损益与交易性金融资产比：公允价值变动损益 / 交易性金融资产期末余额 × 100% | H10: 投资收益同比增速：(本期投资收益 - 上期投资收益) / |上期投资收益| × 100% | I10: 其他收益占净利润比：其他收益 / 净利润 × 100% | J10: 非经常性损益项目数量：非经常性损益明细表中列示的项目个数（金额不为0的项目）
B11: 非经常性损益增速-净利润增速差：非经常性损益同比增速 - 净利润同比增速 | C11: 扣非净利润连续为负年数：连续年度中扣非净利润<0的年数 | D11: 处置子公司股权收益占净利润比：处置子公司股权产生的投资收益 / 净利润 × 100% | E11: 政府补助占营收比：计入当期损益的政府补助 / 营业收入 × 100% | F11: 债务重组损益净额：债务重组收益 - 债务重组损失 | G11: 公允价值变动+投资收益合计占净利润比：(公允价值变动损益 + 投资收益) / 净利润 × 100% | H11: 处置长期股权投资收益占投资收益比：处置长期股权投资产生的投资收益 / 投资收益合计 × 100% | I11: 营业外收支净额占净利润比：(营业外收入 - 营业外支出) / 净利润 × 100% | J11: 非经常性损益结构集中度：非经常性损益中金额最大的单一项目 / 非经常性损益合计 × 100%
B12: 非经常性损益占利润总额比：非经常性损益 / 利润总额 × 100% | C12: 净利润扭亏但扣非仍亏判断：IF(净利润_本期>0 AND 净利润_上期<0 AND 扣非净利润_本期<0, 1, 0) | D12: 资产处置收益与固定资产净值比：非流动资产处置损益 / 固定资产账面价值 × 100% | E12: 与收益相关政府补助占比：与收益相关的政府补助 / 政府补助合计 × 100% | H12: 非主业投资收益占净利润比：(处置交易性金融资产收益 + 处置其他权益工具投资收益 + 理财收益 + 处置长期股权投资收益) / 净利润 × 100% | I12: 营业外收入中"其他"项占比：营业外收入明细中"其他"项金额 / 营业外收入合计 × 100% | J12: 扣非净利润连续为负年数：连续年度中扣除非经常性损益的净利润<0的年数
E13: 政府补助连续3年占净利润比均值：近3年政府补助占净利润比的算术平均值 | J13: 非经常性损益占比趋势斜率：近3年非经常性损益占净利润比的线性回归斜率（逐年变化方向）
A16: 数据来源Data_Source | B16: 利润表 + 年报附注 | C16: 利润表 | D16: 年报附注 | E16: 年报附注 | F16: 年报附注 | G16: 利润表 | H16: 利润表 + 年报附注 | I16: 利润表 + 年报附注 | J16: 利润表 + 年报附注
A17: 阈值Threshold | B17: 非经常性损益占净利润比：高风险：>100%，关注：50%~100%，正常：<50% | C17: 净利润与扣非净利润差值：高风险：差值>净利润的50%且净利润>0，关注：差值为净利润的30%~50%，正常：<30% | D17: 非流动资产处置损益占净利润比：高风险：>50%，关注：20%~50%，正常：<20% | E17: 政府补助占净利润比：高风险：>60%，关注：30%~60%，正常：<30% | F17: 债务重组收益占净利润比：高风险：>40%，关注：20%~40%，正常：<20%（无债务重组收益为最佳） | G17: 公允价值变动损益占净利润比：高风险：>30%（收益）或<-20%（损失），关注：10%~30%，正常：<10% | H17: 投资收益占净利润比：高风险：>50%，关注：30%~50%，正常：<30% | I17: 营业外收入占净利润比：高风险：>30%，关注：10%~30%，正常：<10% | J17: 非经常性损益年度波动率：高风险：>100%，关注：50%~100%，正常：<50%
B18: 非经常性损益占营收比：高风险：>5%，关注：2%~5%，正常：<2% | C18: 扣非净利润占净利润比：高风险：<0%（扣非为负但净利润为正），关注：0%~50%，正常：>50% | D18: 非流动资产处置损益占非经常性损益比：高风险：>60%，关注：30%~60%，正常：<30% | E18: 政府补助占非经常性损益比：高风险：>70%，关注：40%~70%，正常：<40% | F18: 非货币性资产交换收益占净利润比：高风险：>30%，关注：10%~30%，正常：<10%（无非货币性交换收益为最佳） | G18: 公允价值变动损益同比增速：高风险：同比变动>200%或由负转正且金额>净利润20%，关注：变动50%~200%，正常：<50% | H18: 投资收益占营业利润比：高风险：>40%，关注：20%~40%，正常：<20% | I18: 营业外收入同比增速：高风险：同比增长>100%且金额>净利润20%，关注：增长50%~100%，正常：<50% | J18: 非经常性损益连续3年占净利润比均值：高风险：均值>60%，关注：均值30%~60%，正常：均值<30%
B19: 非经常性损益同比增速：高风险：同比增长>100%且净利润同比增长<30%，关注：增长50%~100%，正常：<50% | C19: 净利润为正扣非为负判断：高风险：=1（净利润为正但扣非为负），正常：=0 | D19: 资产处置收益同比增速：高风险：同比增长>200%或由负转正且金额>净利润30%，关注：增长50%~200%，正常：<50% | E19: 政府补助同比增速：高风险：同比增长>100%且无重大政策依据，关注：增长50%~100%，正常：<50% | F19: 债务重组收益同比变动：高风险：本期新增债务重组收益>净利润30%（上期为0或极小），关注：新增10%~30%，正常：无重大变动 | G19: 公允价值变动损益与交易性金融资产比：高风险：>20%（年化收益率异常偏高），关注：10%~20%，正常：<10%（参考市场平均年化收益率） | H19: 投资收益同比增速：高风险：同比增长>100%且营业利润同比增长<30%，关注：增长50%~100%，正常：<50% | I19: 其他收益占净利润比：高风险：>50%，关注：30%~50%，正常：<30% | J19: 非经常性损益项目数量：高风险：项目数≤2且合计金额>净利润50%（过度集中），或项目数>15（异常分散），关注：3~5个，正常：5~12个
B20: 非经常性损益增速-净利润增速差：高风险：>50个百分点，关注：20~50个百分点，正常：<20个百分点 | C20: 扣非净利润连续为负年数：高风险：连续≥2年扣非为负，关注：连续1年扣非为负，正常：扣非持续为正 | D20: 处置子公司股权收益占净利润比：高风险：>40%，关注：20%~40%，正常：<20% | E20: 政府补助占营收比：高风险：>3%，关注：1%~3%，正常：<1% | F20: 债务重组损益净额：高风险：净额>0且占净利润>30%，关注：净额>0且占比10%~30%，正常：净额≈0或<10% | G20: 公允价值变动+投资收益合计占净利润比：高风险：>60%，关注：30%~60%，正常：<30% | H20: 处置长期股权投资收益占投资收益比：高风险：>50%，关注：30%~50%，正常：<30% | I20: 营业外收支净额占净利润比：高风险：>25%（净收益），关注：10%~25%，正常：<10% | J20: 非经常性损益结构集中度：高风险：>70%，关注：50%~70%，正常：<50%
B21: 非经常性损益占利润总额比：高风险：>80%，关注：50%~80%，正常：<50% | C21: 净利润扭亏但扣非仍亏判断：高风险：=1（上年亏损本年扭亏但扣非仍亏），正常：=0 | D21: 资产处置收益与固定资产净值比：高风险：>10%，关注：5%~10%，正常：<5% | E21: 与收益相关政府补助占比：高风险：>90%且一次性计入当期损益，关注：70%~90%，正常：<70% | H21: 非主业投资收益占净利润比：高风险：>40%，关注：20%~40%，正常：<20% | I21: 营业外收入中"其他"项占比：高风险：>40%，关注：20%~40%，正常：<20% | J21: 扣非净利润连续为负年数：高风险：连续≥3年扣非为负，关注：连续2年扣非为负，正常：扣非持续为正或偶发1年为负
E22: 政府补助连续3年占净利润比均值：高风险：均值>50%，关注：均值30%~50%，正常：均值<30% | J22: 非经常性损益占比趋势斜率：高风险：斜率>15（占比逐年快速上升），关注：斜率5~15，正常：斜率绝对值<5或为负
A24: RAG_Keywords | B24: 非经常性损益、非经常性损益项目及金额、非经常性损益合计、非经常性损益占比、扣除非经常性损益的净利润、扣非净利润、归母净利润、净利润、利润总额、营业利润、非经常性损益明细、非经常性损益披露、非经常性损益同比、非经常性损益变动 | C24: 扣非净利润、扣除非经常性损益的净利润、净利润为正扣非为负、扭亏为盈、连续亏损、保壳、摘帽、退市风险警示、*ST、ST、主要会计数据、非经常性损益、净利润与扣非净利润差异、归属于上市公司股东的净利润、归属于上市公司股东的扣除非经常性损益的净利润 | D24: 非流动资产处置损益、资产处置收益、处置固定资产损益、处置无形资产损益、处置长期股权投资、处置子公司股权、资产处置、非货币性资产交换、资产处置损益、营业外收入处置、投资收益处置、年末处置资产、突击处置、资产出售、股权转让收益、处置对价公允性 | E24: 政府补助、计入当期损益的政府补助、与资产相关的政府补助、与收益相关的政府补助、递延收益、政府补助明细、财政补贴、财政拨款、税收返还、即征即退、政府补助文件、政府补助到账、政府补助确认、政府补助摊销、其他收益、营业外收入政府补助 | F24: 债务重组收益、债务重组损失、债务豁免、债务重组、非货币性资产交换、非货币性交易、换入资产、换出资产、债务重组损益、债权人豁免、修改其他债务条件、以资产清偿债务、将债务转为资本、营业外收入债务重组、投资收益债务重组 | G24: 公允价值变动损益、公允价值变动收益、交易性金融资产、交易性金融负债、投资性房地产公允价值、其他非流动金融资产、公允价值变动、估值模型、估值技术、可观察输入值、不可观察输入值、公允价值层级、金融资产分类、FVTPL、FVOCI | H24: 投资收益、投资收益明细、处置长期股权投资收益、权益法核算投资收益、成本法核算投资收益、处置交易性金融资产收益、理财收益、委托理财、联营企业投资收益、合营企业投资收益、投资收益同比、投资收益占比、非主业投资、金融投资收益 | I24: 营业外收入、营业外支出、营业外收支、捐赠收入、违约金收入、罚款收入、无法支付的应付款项、其他收益、营业外收入明细、营业外支出明细、非流动资产毁损报废损失、赔偿收入、政府补助以外的其他收益、营业外收入其他项、预计负债 | J24: 非经常性损益持续性、非经常性损益波动、非经常性损益结构、非经常性损益项目数量、非经常性损益集中度、扣非净利润连续为负、非经常性损益占比趋势、非经常性损益年度波动率、非经常性损益同比变动、非经常性损益可持续性、利润质量、盈利质量、核心利润、主业利润
A25: Evidence_Required

Sheet R004
A1: 风险编号riskid | B1: R004
A2: 风险名称riskname | B2: 少计/延迟确认成本
A3: 风险类型Risk_Category | B3: 成本与费用类舞弊
A4: 定义解释Definition | B4: 少计/延迟确认成本是指企业通过已发生成本不入账、存货结转成本不足、人为压低营业成本、费用体外化（由大股东或关联方承担公司费用）、将应费用化的支出资本化（如研发支出、利息支出）、延长折旧摊销年限、少计提资产减值准备等方式，少计或延迟确认成本费用，以虚增当期利润。核心特征：毛利率异常持续走高、存货规模持续变大、收入扩张但期间费用不跟随增长、研发资本化比例远高于同行。常见手段：①已发生成本不入账，存货结转成本不足，人为压低营业成本；②大股东体外支付公司广告费、研发费、销售佣金，账面少记销售/管理/研发费用；③把非研发支出计入研发费用，资本化时点不合理，把应当费用化的支出资本化。
A5: 信号编号Signal ID | B5: R004-S01 | C5: R004-S02 | D5: R004-S03 | E5: R004-S04 | F5: R004-S05 | G5: R004-S06 | H5: R004-S07 | I5: R004-S08 | J5: R004-S09
A6: 信号名称Signal_Name | B6: 毛利率异常持续走高 | C6: 存货规模持续变大/存货与营业成本背离 | D6: 营业成本增速与营收增速背离 | E6: 期间费用不跟随收入增长（费用体外化） | F6: 研发支出资本化比例异常 | G6: 折旧/摊销政策异常 | H6: 资产减值准备计提不足 | I6: 应付账款/应付票据异常（延迟确认采购成本） | J6: 预提费用/预计负债计提不足
A7: 信号类型Signal_Type | B7: 定量 | C7: 定量 | D7: 定量 | E7: 定量 | F7: 定量 | G7: 定量 | H7: 定量 | I7: 定量 | J7: 定量
A8: 公式Formula | B8: 销售毛利率：(营业收入 - 营业成本) / 营业收入 × 100% | C8: 存货同比增速：(本期存货期末余额 - 上期存货期末余额) / 上期存货期末余额 × 100% | D8: 营业成本同比增速：(本期营业成本 - 上期营业成本) / 上期营业成本 × 100% | E8: 销售费用率：销售费用 / 营业收入 × 100% | F8: 研发支出资本化率：开发支出资本化金额 / 研发支出总额 × 100%，研发支出总额=研发费用+开发支出资本化金额 | G8: 固定资产折旧率：本期累计折旧增加额 / 固定资产原值平均余额 × 100% | H8: 存货跌价准备计提率：存货跌价准备期末余额 / 存货账面余额 × 100% | I8: 应付账款同比增速：(本期应付账款期末余额 - 上期应付账款期末余额) / 上期应付账款期末余额 × 100% | J8: 预计负债同比增速：(本期预计负债期末余额 - 上期预计负债期末余额) / 上期预计负债期末余额 × 100%
B9: 毛利率同比变动：本期销售毛利率 - 上期销售毛利率 | C9: 存货增速-营业成本增速差：存货同比增速 - 营业成本同比增速 | D9: 营收增速-成本增速差：营业收入同比增速 - 营业成本同比增速 | E9: 管理费用率：管理费用 / 营业收入 × 100% | F9: 资本化研发支出占净利润比：开发支出资本化金额 / 净利润 × 100% | G9: 折旧率同比变动：本期固定资产折旧率 - 上期固定资产折旧率 | H9: 坏账准备计提率：坏账准备期末余额 / 应收账款账面余额 × 100% | I9: 应付账款增速-营业成本增速差：应付账款同比增速 - 营业成本同比增速 | J9: 预计负债占营收比：预计负债期末余额 / 营业收入 × 100%
B10: 毛利率行业偏离度：公司销售毛利率 - 行业平均销售毛利率 | C10: 存货增速-营收增速差：存货同比增速 - 营业收入同比增速 | D10: 营业成本率：营业成本 / 营业收入 × 100% | E10: 研发费用率：研发费用 / 营业收入 × 100% | F10: 开发支出同比增速：(本期开发支出期末余额 - 上期开发支出期末余额) / 上期开发支出期末余额 × 100% | G10: 无形资产摊销率：本期累计摊销增加额 / 无形资产原值平均余额 × 100% | H10: 资产减值损失占营收比：资产减值损失 / 营业收入 × 100%（损失以正数列示） | I10: 应付账款周转天数：应付账款平均余额 / 营业成本 × 365，应付账款平均余额=(期初+期末应付账款)/2 | J10: 预计负债占营收比同比变动：本期预计负债占营收比 - 上期预计负债占营收比
B11: 毛利率连续上升年数：连续年度中销售毛利率逐年上升的年数 | C11: 存货周转率：营业成本 / 平均存货余额，平均存货余额=(期初存货+期末存货)/2 | D11: 营业成本率同比变动：本期营业成本率 - 上期营业成本率 | E11: 期间费用率合计：(销售费用+管理费用+研发费用+财务费用) / 营业收入 × 100% | F11: 研发投入总额：研发费用 + 开发支出资本化金额 | G11: 折旧政策变更判断：IF(近3年发生折旧年限/折旧方法/残值率变更, 1, 0) | H11: 信用减值损失占营收比：信用减值损失 / 营业收入 × 100%（损失以正数列示） | I11: 应付票据占应付款项比：应付票据 / (应付票据 + 应付账款) × 100% | J11: 销售费用中预提费用占比：销售费用中预提的保修费/返利费等 / 销售费用合计 × 100%
B12: 主营业务毛利率：(主营业务收入 - 主营业务成本) / 主营业务收入 × 100% | C12: 存货周转天数：365 / 存货周转率，或 = 平均存货余额 / 营业成本 × 365 | D12: Q4营业成本占比：第四季度营业成本 / 全年营业成本 × 100% | E12: 销售费用增速-营收增速差：销售费用同比增速 - 营业收入同比增速 | F12: 研发资本化率行业偏离度：公司研发支出资本化率 - 行业平均研发支出资本化率 | G12: 固定资产成新率：固定资产净值 / 固定资产原值 × 100% | H12: 存货跌价准备计提率同比变动：本期存货跌价准备计提率 - 上期存货跌价准备计提率 | I12: 应付账款占营业成本比：应付账款期末余额 / 营业成本 × 100% | J12: 预计负债连续下降年数：连续年度中预计负债期末余额逐年下降的年数
B13: 毛利率季度波动率：近4个季度销售毛利率的样本标准差 | C13: 存货占总资产比：存货期末余额 / 总资产期末余额 × 100% | D13: 营业成本季度波动率：近4个季度营业成本率的标准差 | E13: 期间费用率同比变动：本期期间费用率合计 - 上期期间费用率合计 | F13: 开发支出占无形资产比：开发支出期末余额 / (开发支出+无形资产) × 100% | G13: 折旧费用占营收比：折旧费用 / 营业收入 × 100% | H13: 商誉减值准备计提率：商誉减值准备期末余额 / 商誉账面余额 × 100% | I13: 应付账款周转天数同比变动：本期应付账款周转天数 - 上期应付账款周转天数 | J13: 其他应付款中预提费用占比：其他应付款中预提费用/应付暂估 / 其他应付款合计 × 100%
E14: 销售费用率行业偏离度：公司销售费用率 - 行业平均销售费用率
A16: 数据来源Data_Source | B16: 利润表 + 利润表附注 | C16: 利润表 + 资产负债表 | D16: 利润表 | E16: 利润表 | F16: 利润表 + 年报附注 + 资产负债表 | G16: 年报附注 + 现金流量表补充资料 + 资产负债表 + 资产负债表附注 | H16: 利润表 + 资产负债表附注 | I16: 资产负债表 | J16: 利润表附注 + 资产负债表 + 资产负债表附注
A17: 阈值Threshold | B17: 销售毛利率：高风险：同比上升>8个百分点且无合理理由，关注：上升5~8个百分点，正常：<5个百分点 | C17: 存货同比增速：高风险：同比增长>50%且营业成本增速<20%，关注：增长30%~50%，正常：<30% | D17: 营业成本同比增速：高风险：营收增长>20%但营业成本增长<5%，关注：营收增长但成本增速为营收增速的50%以下，正常：成本增速与营收增速基本匹配 | E17: 销售费用率：高风险：同比下降>3个百分点且营收增长>15%，关注：下降2~3个百分点，正常：波动<2个百分点 | F17: 研发支出资本化率：高风险：>60%，关注：40%~60%，正常：<40%（A股平均约10%~25%） | G17: 固定资产折旧率：高风险：同比下降>2个百分点且无合理理由，关注：下降1~2个百分点，正常：波动<1个百分点 | H17: 存货跌价准备计提率：高风险：<1%且存货规模持续增长，关注：1%~3%，正常：>3%（需结合行业属性） | I17: 应付账款同比增速：高风险：营业成本增长>20%但应付账款增长<5%或为负，关注：成本增长但应付账款增速为成本增速50%以下，正常：与营业成本增速基本匹配 | J17: 预计负债同比增速：高风险：同比下降>30%且营业收入增长>15%，关注：下降15%~30%，正常：与营收匹配增长或稳定
B18: 毛利率同比变动：高风险：同比上升>8个百分点，关注：上升5~8个百分点，正常：波动<5个百分点 | C18: 存货增速-营业成本增速差：高风险：>25个百分点，关注：15~25个百分点，正常：<15个百分点 | D18: 营收增速-成本增速差：高风险：>25个百分点，关注：15~25个百分点，正常：<15个百分点 | E18: 管理费用率：高风险：同比下降>3个百分点且营收增长，关注：下降2~3个百分点，正常：波动<2个百分点 | F18: 资本化研发支出占净利润比：高风险：>50%（扣除资本化后净利润可能为负或大幅下降），关注：30%~50%，正常：<30% | G18: 折旧率同比变动：高风险：同比下降>2个百分点，关注：下降1~2个百分点，正常：波动<1个百分点 | H18: 坏账准备计提率：高风险：同比下降>2个百分点且应收账款增长>20%，关注：下降1~2个百分点，正常：波动<1个百分点或上升 | I18: 应付账款增速-营业成本增速差：高风险：<-25个百分点（应付账款增速远低于成本增速），关注：-15~-25个百分点，正常：差异<15个百分点 | J18: 预计负债占营收比：高风险：连续2年下降且营收增长，关注：同比下降>20%，正常：稳定或随营收增长
B19: 毛利率行业偏离度：高风险：高于行业均值>10个百分点，关注：高于行业均值5~10个百分点，正常：偏离<5个百分点 | C19: 存货增速-营收增速差：高风险：>30个百分点，关注：15~30个百分点，正常：<15个百分点 | D19: 营业成本率：高风险：同比下降>5个百分点且无合理理由，关注：下降3~5个百分点，正常：波动<3个百分点 | E19: 研发费用率：高风险：同比下降>2个百分点且公司宣称研发投入加大，关注：下降1~2个百分点，正常：稳定或上升 | F19: 开发支出同比增速：高风险：同比增长>100%且净利润同比增长<30%，关注：增长50%~100%，正常：<50% | G19: 无形资产摊销率：高风险：同比下降>3个百分点且无合理理由，关注：下降1.5~3个百分点，正常：波动<1.5个百分点 | H19: 资产减值损失占营收比：高风险：连续2年下降且资产规模增长>20%，关注：同比下降>50%，正常：与资产规模匹配 | I19: 应付账款周转天数：高风险：同比缩短>20天且营业成本增长，关注：缩短10~20天，正常：波动<10天或延长 | J19: 预计负债占营收比同比变动：高风险：同比下降>1个百分点且营收增长>15%，关注：下降0.5~1个百分点，正常：波动<0.5个百分点
B20: 毛利率连续上升年数：高风险：连续≥3年毛利率上升且营收增长，关注：连续2年上升，正常：波动上升或下降 | C20: 存货周转率：高风险：同比下降>20%且低于行业均值，关注：下降10%~20%，正常：下降<10%或上升 | D20: 营业成本率同比变动：高风险：同比下降>5个百分点，关注：下降3~5个百分点，正常：波动<3个百分点 | E20: 期间费用率合计：高风险：同比下降>5个百分点且营收增长>15%，关注：下降3~5个百分点，正常：波动<3个百分点 | F20: 研发投入总额：中间变量，不单独判断 | G20: 折旧政策变更判断：高风险：=1且变更方向为延长年限/降低折旧率，关注：=1但变更方向不明确，正常：=0 | H20: 信用减值损失占营收比：高风险：连续2年下降且应收账款增长>20%，关注：同比下降>50%，正常：与应收账款规模匹配 | I20: 应付票据占应付款项比：高风险：同比上升>15个百分点，关注：上升10~15个百分点，正常：波动<10个百分点 | J20: 销售费用中预提费用占比：高风险：=0或<1%且行业惯例需计提（如家电、汽车、消费品），关注：<行业均值50%，正常：与行业惯例匹配
B21: 主营业务毛利率：高风险：主营业务毛利率同比上升>8个百分点，关注：上升5~8个百分点，正常：<5个百分点 | C21: 存货周转天数：高风险：同比增加>30天且高于行业均值，关注：增加15~30天，正常：增加<15天 | D21: Q4营业成本占比：高风险：<20%（成本延迟结转至次年），关注：20%~25%，正常：25%~30%（均匀分布约25%） | E21: 销售费用增速-营收增速差：高风险：<-25个百分点（销售费用增速远低于营收增速），关注：-15~-25个百分点，正常：差异<15个百分点 | F21: 研发资本化率行业偏离度：高风险：高于行业均值>30个百分点，关注：高于行业均值15~30个百分点，正常：偏离<15个百分点 | G21: 固定资产成新率：高风险：成新率持续下降但折旧率同时下降（折旧不足），关注：成新率<40%且折旧率下降，正常：成新率与折旧率匹配 | H21: 存货跌价准备计提率同比变动：高风险：同比下降>1个百分点且存货增长>20%，关注：下降0.5~1个百分点，正常：波动<0.5个百分点或上升 | I21: 应付账款占营业成本比：高风险：同比下降>10个百分点且营业成本增长，关注：下降5~10个百分点，正常：波动<5个百分点 | J21: 预计负债连续下降年数：高风险：连续≥2年下降且营收增长，关注：连续1年下降且营收增长，正常：稳定或增长
B22: 毛利率季度波动率：高风险：标准差>5个百分点，关注：3~5个百分点，正常：<3个百分点 | C22: 存货占总资产比：高风险：连续2年上升且占比>30%，关注：连续2年上升且占比20%~30%，正常：稳定或下降 | D22: 营业成本季度波动率：高风险：标准差>5个百分点，关注：3~5个百分点，正常：<3个百分点 | E22: 期间费用率同比变动：高风险：同比下降>5个百分点，关注：下降3~5个百分点，正常：波动<3个百分点 | F22: 开发支出占无形资产比：高风险：>30%且持续上升，关注：20%~30%，正常：<20% | G22: 折旧费用占营收比：高风险：同比下降>1个百分点且营收增长>15%，关注：下降0.5~1个百分点，正常：波动<0.5个百分点 | H22: 商誉减值准备计提率：高风险：=0且商誉占总资产>20%且被投资单位业绩下滑，关注：计提率<5%且商誉规模大，正常：按减值测试结果计提 | I22: 应付账款周转天数同比变动：高风险：同比缩短>20天，关注：缩短10~20天，正常：波动<10天 | J22: 其他应付款中预提费用占比：高风险：同比下降>20个百分点且成本费用增长，关注：下降10~20个百分点，正常：稳定
E23: 销售费用率行业偏离度：高风险：低于行业均值>50%（即仅为行业一半以下），关注：低于行业均值30%~50%，正常：偏离<30%
A24: RAG_Keywords | B24: 毛利率、销售毛利率、主营业务毛利率、综合毛利率、毛利率变动、毛利率同比、毛利率环比、毛利率波动、毛利率行业对比、营业成本、营业总成本、主营业务成本、营业成本率、成本率、成本结转、存货结转成本、成本跨期、成本延迟确认、已发生成本不入账、压低营业成本 | C24: 存货、存货余额、存货账面余额、存货账面价值、存货同比、存货增长、存货规模、存货周转率、存货周转天数、存货占比、存货结构、库存商品、发出商品、原材料、在途物资、委托加工物资、存货跌价准备、存货积压、存货周转减慢、平均存货余额 | D24: 营业成本、营业成本同比、营业成本增长、营业成本率、成本率、成本增速、营收增速、成本增速差、营业成本跨期、成本延迟结转、Q4营业成本、第四季度成本、分季度营业成本、季度成本率、成本结转不足、成本确认、成本完整性、成本截止 | E24: 销售费用、管理费用、研发费用、财务费用、期间费用、销售费用率、管理费用率、研发费用率、期间费用率、费用体外化、费用增长、费用增速、费用不跟随收入增长、大股东承担费用、关联方承担费用、广告费、销售佣金、销售费用明细、管理费用明细、降本增效 | F24: 研发支出、研发费用、开发支出、研发投入、研发资本化、资本化率、资本化金额、费用化金额、研发投入资本化比例、开发支出余额、开发支出增长、研发项目、资本化时点、开发阶段、研究阶段、研发投入明细、高新技术企业、研发费用加计扣除 | G24: 固定资产折旧、累计折旧、折旧率、折旧年限、折旧方法、残值率、直线法、加速折旧法、年数总和法、双倍余额递减法、固定资产原值、固定资产净值、固定资产成新率、无形资产摊销、累计摊销、摊销年限、摊销方法、会计估计变更、折旧政策变更 | H24: 资产减值损失、信用减值损失、存货跌价准备、坏账准备、固定资产减值准备、商誉减值准备、无形资产减值准备、在建工程减值准备、减值计提、减值计提率、减值转回、资产减值、商誉减值、减值测试、可变现净值、预期信用损失、账龄分析、资产减值明细 | I24: 应付账款、应付票据、应付账款余额、应付账款同比、应付账款增长、应付账款周转天数、应付账款周转率、应付款项、应付票据占比、银行承兑汇票、商业承兑汇票、预付账款、采购成本、供应商、应付账款账龄、应付账款明细、截止性测试、应付账款暂估 | J24: 预计负债、预提费用、产品质量保证、销售返利、销售退回、未决诉讼、亏损合同、弃置费用、预计负债余额、预计负债同比、预计负债计提、预计负债明细、其他应付款、应付暂估款、预提费用明细、保修费用、返利计提、会计估计变更
A25: Evidence_Required

Sheet R005
A1: 风险编号riskid | B1: R005
A2: 风险名称riskname | B2: 期间费用少计与账外承担风险
A3: 风险类型Risk_Category | B3: 成本与费用类舞弊
A4: 定义解释Definition | B4: 企业通过账内少确认 / 跨期延后确认期间费用，或由实控人、关联方体外代垫经营支出、账外承担上市公司费用，不在账面确认相关成本费用，虚增当期利润。
A5: 信号编号Signal ID | B5: R005-S01 | C5: R005-S02 | D5: R005-S03 | E5: R005-S04 | F5: R005-S05 | G5: R005-S06
A6: 信号名称Signal_Name | B6: 期间费用率异常下降 | C6: 费用增速与营收增速严重背离 | D6: 人力薪酬与员工规模不匹配 | E6: 费用现金流出与账面费用不匹配 | F6: 其他类期间费用占比异常 | G6: 业务扩张与费用变动逻辑不匹配
A7: 公式Formula | B7: 销售费用率=销售费用÷营业收入 管理费用率=管理费用÷营业收入 研发费用率=研发费用÷营业收入 期间费用合计率=(销售+管理+ 研发费用)÷营业收入 | C7: 销售费用增长率=(本期销售费用‑上期销售费用)÷上期销售费用 营业收入增长率=(本期营收‑上期营收)÷上期营收 费用‑营收偏离度=销售费用增长率‑营业收入增长率 | D7: 人均薪酬=当期薪酬总费用÷平均员工人数员工 总人数变动率=(本期平均员工‑上期平均员工)÷上期平均员工 | E7: 支付的其他与经营活动有关的现金 ÷ 账面期间费用合计 | F7: 其他费用÷当期期间费用总额 | G7: 业务扩张幅度 vs 期间费用变动幅度（无直接计算公式，依赖业务文本 + 财务指标联合判断）
A8: 信号类型Signal_Type | B8: 定量 | C8: 定量 | D8: 定量 | E8: 定量 | F8: 定量 | G8: 定性+定量
A9: 数据来源Data_Source | B9: 利润表、营业收入、销售 / 管理 / 研发费用附注 | C9: 利润表、营业收入、期间费用附注 | D9: 利润表、应付职工薪酬附注、年报员工情况披露 | E9: 现金流量表、利润表期间费用附注 | F9: 利润表期间费用明细附注 | G9: 年报业务描述、人员披露、分部报告、前五大供应商附注
A10: 阈值Threshold | B10: 正常 | C10: 指标1：期间费用率对比自身历史2-3年：波动≤5 个百分点 指标2：期间费用率对比同行业中位数：与行业中位数偏差≤3pct | D10: 费用‑营收偏离度：‑10% ≤偏离度 ≤+10% | E10: 人员扩张，薪酬总额同步上涨 | F10: 支付其他经营现金 / 账面期间费用：0.7-1.3 | G10: 其他费用占期间费用比重：普通行业≤15%；营销类行业≤20%
B11: 关注 | C11: 较历史下降 5‑10pct，无合理解释 低于行业中位数 3‑8pct，业务模式无本质差异 | D11: ‑20% ≤偏离度＜‑10% | E11: 员工增加，但薪酬总额提升不足 | F11: 0.5-0.7或1.3-1.6 | G11: 普通行业 15%‑25%；营销类 20%‑30%
B12: 高风险 | C12: 较历史下降＞10pct，无合理解释 低于行业中位数＞8pct，业务模式无本质差异 | D12: 偏离度＜‑20%，营收扩张，费用几乎不增长 | E12: 员工大幅扩招，薪酬总额几乎不增长，无外包替代披露 | F12: ＜0.5，往来科目无法解释缺口 | G12: 普通行业＞25%；营销类＞30%，附注无明细拆分
A13: RAG_Keywords | B13: 销售费用 管理费用 研发费用 期间费用 费用率 推广费 广告费 服务费 | C13: 费用增长率 营业收入增长 费用‑收入弹性同比变动 | D13: 应付职工薪酬 员工人数 人均薪酬 工资 奖金 社保 | E13: 支付的其他与经营活动有关的现金 经营现金流出 费用付现 | F13: 其他费用 咨询费 服务费 中介机构费 差旅费 | G13: 关联方代垫费用 体外报销 市场推广 渠道费 业务扩张
A14: Evidence_Required | B14: 财务数据 + 年报原文

Sheet R006
A1: 风险编号riskid | B1: R006
A2: 风险名称riskname | B2: 研发费用舞弊
A3: 风险类型Risk_Category | B3: 成本与费用类舞弊
A4: 定义解释Definition | B4: 企业通过操纵研发支出的资本化与费用化处理，或虚增研发投入金额，虚增资产或调节利润。常见手段：将不满足资本化条件的支出计入开发支出，减少当期费用虚增利润；虚构研发项目、研发劳务虚增研发投入，用于套取政府补助、维持高新技术企业资质。
A5: 信号编号Signal ID | B5: R006-S01 | C5: R006-S02 | D5: R006-S03 | E5: R006-S04 | F5: R006-S05 | G5: R006-S06
A6: 信号名称Signal_Name | B6: 研发资本化率异常偏高 | C6: 研发投入强度异常 | D6: 人均研发投入异常 | E6: 资本化研发支出与开发支出/无形资产勾稽异常 | F6: 研发投入现金流出与账面投入不匹配 | G6: 研发投入与研发产出不匹配
A7: 公式Formula | B7: 研发资本化率=当期资本化研发支出÷研发投入总额 研发投入总额=费用化研发费用+资本化研发支出 | C7: 研发投入强度=研发投入总额÷营业收入 研发费用率=研发费用÷营业收入 | D7: 人均研发投入=当期研发投入总额÷平均研发人员数 人均研发投入变动率=(本期-上期)÷上期 | E7: 开发支出期末-期初差额=当期资本化研发支出-当期转入无形资产-当期摊销 资本化支出÷当期开发支出增加额 | F7: 支付给职工及为职工支付的现金(研发相关)÷研发投入中薪酬部分 "购买商品、接受劳务支付的现金"中研发相关部分 | G7: 研发投入增长率 vs 新增专利/新产品/新业务收入增长率 研发项目数量、研发人员规模 vs 研发投入增速
A8: 信号类型Signal_Type | B8: 定量 （纵向+横向对比） | C8: 定量 | D8: 定量 | E8: 定量 | F8: 定量 | G8: 定性+定量
A9: 数据来源Data_Source | B9: 利润表研发费用附注、开发支出附注 | C9: 利润表、营业收入、研发投入附注 | D9: 研发投入附注、年报研发人员披露 | E9: 资产负债表开发支出附注、无形资产附注 | F9: 现金流量表、研发投入附注 | G9: 年报研发项目/专利披露、研发人员、新产品收入
A10: 阈值Threshold | B10: 正常 | C10: 资本化率稳定，波动≤5个百分点；与同行业中位数偏差≤10个百分点 | D10: ≥3%（高新技术企业认定门槛），与公司历史及行业合理区间一致；与历史及行业可比 | E10: 与行业薪资水平、研发阶段匹配，研发人员、项目、投入三者自洽 | F10: 当期资本化支出与开发支出增加额、转入无形资产、摊销之间能完整勾稽 | G10: 比值0.7-1.3，受应付、票据结算可解释
B11: 关注 | C11: 资本化率较自身历史上升5-10个百分点；较同行业中位数高10-20个百分点 | D11: 较自身历史下降5-10个百分点，或低于行业但无规模差异解释；明显低于同行业，业务无研发占比下降解释 | E11: 人均投入显著高于行业薪酬水平，缺乏项目说明 | F11: 存在单一环节无法解释的差额 | G11: 0.5-0.7或1.3-1.6，需核查应付变动
B12: 高风险 | C12: 资本化率较自身历史上升＞10个百分点，且项目进入开发阶段无充分披露；较同行业中位数高＞20个百分点，且开发支出占总研发比重持续攀升 | D12: 投入强度大幅下滑＞10个百分点，或资本化率同步异常上升以维持"研发投入"账面体量；研发投入账面金额大，但费用化金额很小、资本化占比异常高 | E12: 人均研发投入异常高企，同时研发人员数量、研发项目披露笼统；研发投入大额增长，但研发人员基本不变，且无外部研发外包披露 | F12: 开发支出长期大额挂账、很少转入无形资产或摊销，资本化支出持续计入开发支出不结转 | G12: 比值＜0.5，账面列支大额研发投入，但现金流出明显不足，往来无法解释
A13: RAG_Keywords | B13: 研发资本化 开发支出 资本化率 费用化 | C13: 研发投入 研发强度 营业收入 研发费用率 | D13: 研发人员 研发人数 人均研发 研发薪酬 | E13: 开发支出 资本化 转入无形资产 摊销 无形资产 | F13: 研发投入 现金流出 支付现金 研发支出付现 | G13: 研发项目 专利 新产品 研发成果 产业化
A14: Evidence_Required | B14: 财务数据+年报原文；

Sheet R007
A1: 风险编号riskid | B1: R007
A2: 风险名称riskname | B2: 存货造假
A3: 风险类型Risk_Category | B3: 资产类舞弊
A4: 定义解释Definition | B4: 企业通过虚增存货余额、低估跌价风险、藏匿盘亏等方式虚增资产和利润。主要手段：虚构采购、在途或发出商品虚增存货；通过第三方仓储、代保管仓单虚增本不存在的实物存货；存货库龄恶化、市价下跌时低估或延迟计提存货跌价准备；对已发生盘亏的存货不做账务处理继续挂账。参考案例：广州浪奇、金正大、紫鑫药业。
A5: 信号编号Signal ID | B5: R007-S01 | C5: R007-S02 | D5: R007-S03 | E5: R007-S04 | F5: R007-S05 | G5: R007-S06
A6: 信号名称Signal_Name | B6: 存货余额异常增长、周转率下降 | C6: 存货跌价准备计提不足 | D6: 第三方仓储/代保管存货占比异常 | E6: 存货与购销、现金勾稽异常 | F6: 存货库龄结构恶化但未计提跌价 | G6: 存货科目结构性突变（发出商品/在途等）
A7: 公式Formula | B7: 存货增长率=(本期存货-上期存货)÷上期存货 存货周转率=营业成本÷平均存货 存货周转天数=365÷存货周转率 | C7: 存货跌价准备÷存货账面余额 存货跌价准备变动额=期末-期初（结合库龄、市价下跌判断计提是否充分） | D7: 代保管/第三方仓储存货÷存货总额 | E7: 存货增长率-营业成本增长率 存货增加额-(采购现金支出-应付账款变动) 存货增长与销售增长匹配度 | F7: 按库龄分类的存货占比（1年/1-3年/3年以上） 各库龄段跌价准备计提比例 | G7: 发出商品÷存货总额 在途物资/材料采购÷存货总额 各明细科目占比同比变动
A8: 信号类型Signal_Type | B8: 定量 | C8: 定量 | D8: 定量 | E8: 定量 | F8: 定性+定量 | G8: 定量
A9: 数据来源Data_Source | B9: 资产负债表存货附注、利润表营业成本 | C9: 资产负债表存货跌价准备附注、库龄表 | D9: 存货附注、仓储/保管协议披露 | E9: 资产负债表、现金流量表、存货及应付附注 | F9: 存货附注库龄明细、跌价准备计提政策 | G9: 存货附注明细（原材料/在产品/库存商品/发出商品/在途）
A10: 阈值Threshold | B10: 正常 | C10: 两者增速大体匹配（偏离在合理区间）；周转率与自身历史、行业可比水平一致 | D10: 计提比例与库龄结构、行业可比、历史水平匹配；跌价准备随存货规模、市价变动合理波动 | E10: 占比低（一般≤15%），有真实仓储协议支撑 | F10: 存货变动能与采购现金、应付账款、生产成本勾稽 | G10: 库龄结构与历史、行业一致，计提比例匹配
B11: 关注 | C11: 存货增长明显快于成本增长；周转率较历史或同行明显放缓 | D11: 部分账龄段计提明显偏低；存货快速增长但跌价准备未同步增长 | E11: 占比15%-30%，仓储协议、盘点记录披露不充分 | F11: 单一环节存在无法解释差额 | G11: 长期库龄存货占比上升，但计提比例未同步上调
B12: 高风险 | C12: 存货大幅增长，而营业成本/销售基本不增长，无扩产、囤货、原材料涨价解释；存货周转持续显著放缓，库存积压与收入/成本变动严重背离 | D12: 存货市价下跌、库龄恶化，但跌价准备几乎不计提或大幅低于历史/同行合理水平；存货大幅增长、库龄恶化，同时跌价准备未增加或反而下降 | E12: 占比＞30%，大额存货存放第三方/代保管，年报披露仓储情况笼统，无法核实实物（广州浪奇特征） | F12: 存货持续大额增加，但采购现金支出、应付变动无法支撑该增量，无合理说明 | G12: 大量超长库龄/过时/变质存货，跌价准备仍按低比例计提，无市价与处置依据
A13: RAG_Keywords | B13: 存货 库存商品 原材料 发出商品 存货周转率 存货余额 | C13: 存货跌价准备 跌价损失 计提比例 可变现净值 减值测试 | D13: 第三方仓储 代保管 仓单 保税仓 公共仓库 委托保管 | E13: 采购 营业成本 应付账款 现金采购 存货增加 | F13: 库龄 账龄 积压 过时 呆滞 变质 | G13: 发出商品 在途物资 材料采购 原材料 库存商品 存货结构
A14: Evidence_Required | B14: 财务数据+年报原文；

Sheet R008
A1: 风险编号riskid | B1: R008
A2: 风险名称riskname | B2: 虚增在建工程、固定资产、固定资产折旧
A3: 风险类型Risk_Category | B3: 收入舞弊（所属的大类）
A4: 定义解释Definition | B4: 企业通过虚构工程项目、虚增工程量或工程投入等方式虚增在建工程，并可能进一步将虚增的在建工程转入固定资产；在后续期间，对虚增的固定资产计提折旧，还可能导致折旧费用虚增和利润虚减，从而导致资产及相关成本、费用和利润出现虚假记载。利源精制案例中即存在“虚增在建工程→转入固定资产→对虚增固定资产计提折旧”的连续会计处理链条。
A5: 信号编号Signal ID | B5: R008-S01 | C5: R008-S02 | D5: R008-S03 | E5: R008-S04 | F5: R008-S05 | G5: R008-S06
A6: 信号名称Signal_Name | B6: 在建工程异常增长 | C6: 在建工程与实际投入是否匹配 | D6: 在建工程转入固定资产异常 | E6: 固定资产异常增长 | F6: 虚增固定资产相关折旧异常 | G6: 在建工程—固定资产—折旧勾稽关系异常
A7: 信号类型Signal_Type | B7: 定量 | C7: 定量 | D7: 定量 | E7: 定量 | F7: 定量 | G7: 定量
A8: 公式Formula | B8: 在建工程增长率=（本期在建工程−上期在建工程​）/上期在建工程 | C8: 在建工程增加额=本期在建工程-上期在建工程 | D8: 固定资产增加额=本期固定资产-上期固定资产 | E8: 固定资产增长率=(本期固定资产-上期固定资产)/上期固定资产 | F8: 折旧增长率=(本期折旧额-上期折旧额)/上期折旧额 | G8: 链条差额=固定资产增加额-转固金额-外购固定资产-其他增加
B9: 营业收入增长率=（本期营业收入−上期营业收入）/上期营业收入 | C9: 现金支付工程款=购建固定资产、无形资产和其他长期资产支付的现金 | D9: 在建工程转固金额=本期在建工程转入固定资产金额 | E9: 固定资产增长率-营业收入增长率 | F9: 期折旧额/平均固定资产原值
B10: 增长偏离度=在建工程增长率−营业收入增长率 | C10: 投入产出比=在建工程增加额/工程现金支出 | D10: 转固率=本期在建工程转固金额/期初在建工程+本期新增在建工程 | E10: 期末固定资产账面价值/期末总资产 | F10: 折旧变动与固定资产变动偏离=固定资产增长率-折旧增长率
B11: …... | D11: 转固后折旧变化=本期折旧额-上期折旧额 | F11: 实际折旧额与理论折旧额差异=实际折旧额-按披露折旧年限及残值率计算的理论折旧额
A12: 数据来源Data_Source | B12: 资产负债表、利润表、在建工程附注 | C12: 资产负债表、现金流量表、在建工程附注 | D12: 资产负债表、固定资产/在建工程附注 | E12: 资产负债表、利润表 | F12: 资产负债表、现金流量表、固定资产附注
A13: 阈值Threshold | B13: 在建工程增长率的正常范围：与企业经营规模、历史趋势基本一致；关注范围：明显高于企业历史增长水平；高风险范围：大幅高于企业历史水平，且无法由产能扩张、重大项目等解释 | C13: 投入产出比。正常范围：在建工程增加与工程现金支出能够通过应付工程款、预付款、结算时点等解释；关注范围：两者明显不匹配；高风险范围：长期、大额不匹配且无法由项目进度、付款安排等解释 | D13: 核心不是规定“转固率必须多少”，而是看是否达到预定可使用状态后及时转固并计提折旧 | E13: 固定资产增长率-营业收入增长率，其差额的正常范围：固定资产增长与收入、产能、产量、经营规模匹配；关注范围：固定资产增长明显快于收入/经营规模；高风险范围：固定资产大幅增加但产能、收入没有对应提升，且无扩产、技改等合理解释 | F13: 正常范围：折旧变化与固定资产规模、投产时间、折旧年限、残值率、折旧方法一致；关注范围：实际折旧与理论折旧明显偏离；高风险范围：固定资产真实性、转固时间或折旧政策存在异常，并导致折旧明显异常 | G13: 此关系的正常范围：链条能够勾稽；关注范围：单一环节存在无法解释的差额；高风险范围：在建工程增加、转固、固定资产增加、折旧多个环节同时异常
B14: 增长偏离度的正常范围：≤10个百分点；关注范围：>10～30个百分点；高风险范围：>30个百分点 | D14: 转固率：正常范围：转固时间与项目完工/达到可使用状态一致；关注范围：存在明显滞后；高风险范围：已经投入使用仍长期挂在在建工程，且未及时转固、计提折旧
B15: 两指标联动下，正常范围：在建工程增长与收入/产能扩张基本匹配；关注范围：在建工程增长明显快于收入增长；高风险范围：在建工程大幅增长，而收入基本不增长/下降，且无合理业务解释
B17: 北京注协的监管提示明确强调的是：要把固定资产投资规模与经营规模、产能、产量以及营业收入增长进行匹配分析，而不是单独看增长率。
A18: RAG_Keywords | B18: 在建工程 重大在建工程 工程项目 工程进度 工程投入 项目建设 工程预算 工程结算 | C18: 工程投入 工程进度 工程建设 项目投资 建设项目 重大项目 项目预算 项目金额 设备安装 土建工程 | D18: 固定资产 机器设备 房屋建筑物 生产线 设备采购 新增设备 技术改造 产能扩张 生产基地 固定资产增加 | E18: 购置 新增 转入 企业合并 其他增加 处置 报废 固定资产变动 | F18: 在建工程 工程项目 工程进度 转入固定资产 达到预定可使用状态 固定资产 机器设备 累计折旧 折旧方法 折旧年限 预计净残值
A19: Evidence_Required | B19: 财务数据+年报原文
A20: 定性证据 | B20: 是否存在重大项目、扩产、技改、募投项目等合理解释。

Sheet R009
A1: 风险编号riskid | B1: R009
A2: 风险名称riskname | B2: 虚增货币资金
A3: 风险类型Risk_Category | B3: 资产类舞弊
A4: 定义解释Definition | B4: 企业通过伪造银行回单、虚构银行存款或隐瞒实际资金被占用等方式虚增货币资金，导致资产负债表货币资金与银行实际余额、现金流及融资结构不一致。金亚科技案例中存在伪造银行单据、虚增银行存款以及虚列预付工程款的情形。
A5: 信号编号Signal ID | B5: R009-S01 | C5: R009-S02 | D5: R009-S03 | E5: R009-S04 | F5: R009-S05 | G5: R009-S06
A6: 信号名称Signal_Name | B6: 货币资金异常增长 | C6: 货币资金与经营活动现金流不匹配 | D6: 货币资金与有息负债“大存大贷” | E6: 银行存款与银行流水/函证不一致 | F6: 货币资金变动与借款、利息支出不匹配 | G6: 受限资金/资金占用披露异常
A7: 信号类型Signal_Type | B7: 定量 | C7: 定量 | D7: 定量 | E7: 定量 | F7: 定量 | G7: 定量
A8: 公式Formula | B8: 货币资金增长率=(本期货币资金-上期货币资金)/上期货币资金 | C8: 经营活动现金流净额/货币资金 | D8: 有息负债/货币资金 | E8: 账面银行存款余额-银行函证/银行流水余额 | F8: 借款增长率=(本期有息负债-上期有息负债)/上期有息负债 | G8: 受限货币资金/货币资金
B9: 货币资金/总资产 | C9: 货币资金增长额-经营活动现金流净额 | D9: 财务费用/平均有息负债 | E9: 差异率=(账面银行存款-可验证银行余额)/账面银行存款 | F9: 货币资金增长率-有息负债增长率 | G9: 披露的受限资金与借款质押、冻结、司法事项等是否对应
F10: 财务费用/平均有息负债 | G10: 其他应收款/预付款异常增加且资金流向关联方或体外主体的金额
A11: 数据来源Data_Source | B11: 资产负债表、货币资金附注 | C11: 资产负债表、现金流量表 | D11: 资产负债表、借款附注、财务费用 | E11: 货币资金附注、银行函证/银行流水（如可取得） | F11: 资产负债表、现金流量表、借款附注、财务费用 | G11: 货币资金附注、担保/质押/诉讼公告、关联交易及资金占用披露
A12: 阈值Threshold | B12: 正常范围：与历史趋势及经营规模基本一致；关注范围：明显偏离历史趋势或资产结构变化；高风险范围：大幅异常增长且无法由融资、经营、并购等解释 | C12: 正常范围：经营现金流变化与货币资金变动可合理解释；关注范围：货币资金明显增长但经营现金流未同步改善；高风险范围：货币资金大幅增加且经营现金流长期背离、无法解释 | D12: 正常范围：融资规模与现金需求、用途基本匹配；关注范围：同时存在较高货币资金和有息负债；高风险范围：长期高额货币资金与高额有息负债并存且资金用途/可用性无法解释 | E12: 正常范围：可验证余额一致；关注范围：存在需解释的差异；高风险范围：存在重大直接差异或无法取得合理证明 | F12: 正常范围：三者与融资活动一致；关注范围：局部不匹配；高风险范围：多项同时异常且无法解释 | G12: 正常范围：受限原因、质押及资金往来披露一致；关注范围：存在披露或资金用途疑点；高风险范围：资金实际被占用/受限但年报未充分披露
A13: RAG_Keywords | B13: 货币资金 银行存款 库存现金 其他货币资金 银行账户 银行存款余额 大额存款 | C13: 经营活动现金流 经营活动产生的现金流量净额 现金流量表 现金流 回款 | D13: 短期借款 长期借款 有息负债 财务费用 利息支出 大存大贷 | E13: 银行函证 银行流水 银行回单 银行对账单 账户余额 函证回函 | F13: 借款 新增借款 融资 利息 财务费用 大额借款 | G13: 受限货币资金 冻结 质押 保证金 司法冻结 资金占用 关联方 其他应收款 预付款
A14: Evidence_Required | B14: 财务数据+年报原文；如条件允许，应进一步取得银行函证、银行流水或银行对账单等外部证据。 | C14: 财务数据+年报原文+现金流量表；重点核查经营活动现金流与货币资金变动是否具有合理关系。 | D14: 财务数据+借款及财务费用附注；重点关注账面货币资金规模较大同时存在较高有息负债的情形。 | E14: 财务数据+货币资金附注+外部银行证据；账面余额与可验证余额直接冲突时属于强风险证据。 | F14: 财务数据+借款附注+现金流量表；结合融资用途、现金去向及利息支出分析。 | G14: 财务数据+年报受限资金、担保、诉讼、关联方资金往来披露；关注资金是否实际可自由支配。
A15: 定性证据 | B15: 是否存在大额新增融资、重大资产处置、并购、季节性回款等可以合理解释货币资金变化的事项。 | C15: 经营活动现金流与货币资金不必机械相等，应结合应收账款、预付款、存货、应付项目及融资投资活动解释。 | D15: “大存大贷”本身不是造假结论，应进一步核查借款用途、资金受限情况、资金是否实际可使用。 | E15: 金亚科技案例中账面银行日记账余额219,301,259.06元，而实际银行账户余额仅1,389,423.51元，虚增217,911,835.55元，占资产总额16.46%。该案例说明“账面余额与可验证银行余额直接不一致”具有很强的风险识别价值。 | F15: 金亚科技还存在虚列3.1亿元预付工程款并制作虚假合同、银行付款单据的情形，因此货币资金异常应与大额预付款、工程款等科目联动检查。 | G15: 关注受限资金是否被披露、是否与借款质押或司法事项对应；不可自由支配的资金不能简单视同可用现金。

Sheet R010
A1: 风险编号riskid | B1: R010
A2: 风险名称riskname | B2: 商誉减值舞弊
A3: 风险类型Risk_Category | B3: 资产类舞弊
A4: 定义解释Definition | B4: 企业在并购形成大额商誉后，在被收购标的业绩恶化、业绩承诺未达成或资产组可收回金额下降的情况下，通过高估可收回金额、弱化减值测试依据或少计/不计商誉及相关资产减值，延迟确认减值损失，从而虚增资产和利润。ST实达案例中，资产组可收回价值减值测试存在问题，导致少计提资产组中其他资产减值并虚增利润。
A5: 信号编号Signal ID | B5: R010-S01 | C5: R010-S02 | D5: R010-S03 | E5: R010-S04 | F5: R010-S05 | G5: R010-S06
A6: 信号名称Signal_Name | B6: 商誉规模异常 | C6: 被收购标的业绩未达标但未计提减值 | D6: 商誉对应资产组经营表现与减值测试结果不匹配 | E6: 可收回金额关键假设异常 | F6: 减值测试后利润/净资产改善异常 | G6: 商誉及相关资产减值勾稽异常
A7: 信号类型Signal_Type | B7: 定量 | C7: 定量 | D7: 定量 | E7: 定量 | F7: 定量 | G7: 定量
A8: 公式Formula | B8: 商誉/总资产 | C8: 实际业绩-业绩承诺 | D8: 资产组收入增长率 | E8: 预测期收入增长率 | F8: 减值损失/减值前利润 | G8: 商誉减值损失+资产组其他资产减值损失
B9: 商誉/净资产 | C9: 业绩完成率=实际业绩/承诺业绩 | D9: 资产组利润增长率 | E9: 预测期利润率 | F9: 减值测试前后净利润变化 | G9: 资产组账面价值-可收回金额
D10: 资产组经营现金流增长率 | E10: 折现率 | F10: 减值测试前后净资产变化 | G10: 减值测试覆盖资产与实际资产组范围是否一致
E11: 永续增长率
A12: 数据来源Data_Source | B12: 资产负债表、商誉附注 | C12: 商誉附注、收购公告、业绩承诺披露、年报 | D12: 商誉附注、被收购子公司/资产组经营数据 | E12: 商誉减值测试附注、评估报告、关键假设 | F12: 利润表、资产负债表、商誉减值附注 | G12: 商誉附注、资产减值附注、评估报告、收购协议
A13: 阈值Threshold | B13: 正常范围：规模与并购历史及资产结构相匹配；关注范围：商誉占比明显偏高；高风险范围：商誉重大且高度集中于经营恶化资产组 | C13: 正常范围：业绩基本达到或偏差有充分解释；关注范围：明显未达标；高风险范围：连续未达标且无充分减值依据/解释 | D13: 正常范围：经营表现与减值测试预测基本一致；关注范围：实际表现明显弱于预测；高风险范围：经营持续恶化但减值测试仍显示无需/极少减值 | E13: 正常范围：有历史及业务计划依据；关注范围：部分假设明显乐观或缺乏支持；高风险范围：关键假设明显缺乏经营依据并直接支撑高可收回金额 | F13: 正常范围：结果与经营情况一致；关注范围：减值结果对利润影响异常；高风险范围：明显通过少计减值改善利润或净资产 | G13: 正常范围：能够完整勾稽；关注范围：单一环节存在差异；高风险范围：资产组范围、账面价值、可收回金额及减值损失多个环节不一致
A14: RAG_Keywords | B14: 商誉 企业合并 并购 收购 资产组 商誉减值 | C14: 业绩承诺 业绩完成 业绩未达标 承诺利润 承诺收入 未完成业绩 | D14: 资产组 营业收入 净利润 经营活动现金流 产能 经营恶化 | E14: 可收回金额 预计未来现金流量现值 公允价值减处置费用 折现率 永续增长率 预测期 | F14: 资产减值 商誉减值 减值损失 净利润 净资产 扭亏 | G14: 减值测试 资产组账面价值 可收回金额 评估报告 资产组范围 固定资产减值 无形资产减值
A15: Evidence_Required | B15: 财务数据+年报原文+收购/业绩承诺信息；重点取得商誉减值测试关键假设和资产组信息。 | C15: 年报业绩承诺完成情况+商誉附注；关注连续未达标但未出现减值的情况。 | D15: 财务数据+子公司经营信息；重点比较实际经营表现与减值测试预测。 | E15: 商誉减值测试附注/评估报告；重点核查预测增长、利润率、折现率等关键假设是否有经营依据。 | F15: 财务数据+减值测试前后数据；关注减值测试结果是否对利润、净资产产生异常改善作用。 | G15: 商誉及资产组减值测试资料；检查商誉与资产组其他资产减值是否完整、范围是否一致。
A16: 定性证据 | B16: 并购后标的经营恶化、行业周期下行等可以合理解释商誉风险；反之，不能因为存在商誉就直接认定舞弊。 | C16: 业绩承诺未完成本身不是舞弊结论，但连续未达标且长期不计提减值，是重要风险组合。 | D16: ST实达案例中，2019年商誉减值测试涉及资产组可收回价值，因评估报告存在重复加计票据贴现利息等问题，导致少计提资产组其他资产减值87,885,571.55元，虚增当年净利润和净资产同额。该案例支持“资产组经营/估值假设—减值结果—利润影响”的联动检查。 | E16: 预测假设应与历史经营数据、行业情况、预算及实际经营计划相互验证，不能仅因评估报告存在就视为合理。 | F16: 如果减值测试结果与资产组实际经营表现明显背离，应进入二次AI核验，而不是由数值规则直接认定舞弊。 | G16: 商誉减值风险应关注商誉及相关资产组整体，不宜只看商誉余额单项指标。

Sheet R011
A1: 风险编号riskid | B1: R011
A2: 风险名称riskname | B2: 应收账款坏账计提不足
A3: 风险类型Risk_Category | B3: 资产类舞弊
A4: 定义解释Definition | B4: 企业在应收账款已经逾期、回款困难或客户信用风险明显上升的情况下，通过低估预期信用损失、降低坏账计提比例或虚增应收账款等方式少计信用减值损失，虚增资产和利润。爱迪尔案例中存在虚增应收账款并对虚增应收账款不当计提坏账准备的情形。
A5: 信号编号Signal ID | B5: R011-S01 | C5: R011-S02 | D5: R011-S03 | E5: R011-S04 | F5: R011-S05 | G5: R011-S06
A6: 信号名称Signal_Name | B6: 应收账款异常增长 | C6: 应收账款增长与营业收入不匹配 | D6: 逾期应收账款占比异常 | E6: 坏账准备计提比例与账龄/逾期风险不匹配 | F6: 应收账款回款恶化但坏账准备未同步增加 | G6: 应收账款—坏账准备—信用减值损失勾稽异常
A7: 信号类型Signal_Type | B7: 定量 | C7: 定量 | D7: 定量 | E7: 定量 | F7: 定量 | G7: 定量
A8: 公式Formula | B8: 应收账款增长率=(本期应收账款-上期应收账款)/上期应收账款 | C8: 应收账款周转率=营业收入/平均应收账款 | D8: 逾期应收账款/应收账款 | E8: 坏账准备/应收账款 | F8: 经营活动现金流净额/营业收入 | G8: 期末坏账准备-期初坏账准备+核销/转销金额
B9: 营业收入增长率=(本期营业收入-上期营业收入)/上期营业收入 | C9: 应收账款周转天数=365/应收账款周转率 | D9: 一年以上应收账款/应收账款 | E9: 坏账准备/逾期应收账款 | F9: 销售商品、提供劳务收到的现金/营业收入 | G9: 本期信用减值损失
B10: 应收账款增长率-营业收入增长率 | D10: 长期未收回金额/应收账款 | E10: 不同账龄坏账计提比例 | F10: 应收账款增长率-销售回款增长率 | G10: 坏账准备余额与账龄迁徙、逾期余额变化是否匹配
A11: 数据来源Data_Source | B11: 资产负债表、利润表、应收账款附注 | C11: 资产负债表、利润表、应收账款附注、现金流量表 | D11: 应收账款附注、账龄分析 | E11: 应收账款附注、坏账准备政策、预期信用损失披露 | F11: 现金流量表、应收账款附注、客户回款信息 | G11: 应收账款附注、信用减值损失附注、坏账准备变动表
A12: 阈值Threshold | B12: 正常范围：与收入增长及历史趋势匹配；关注范围：应收账款增长明显快于收入；高风险范围：大幅增长且无信用政策、结算方式等合理解释 | C12: 正常范围：与历史及业务周期基本一致；关注范围：周转明显变慢；高风险范围：持续明显恶化且伴随逾期增加、回款困难 | D12: 正常范围：账龄结构与历史一致；关注范围：逾期或长期账龄明显增加；高风险范围：大量长期逾期且无充分回款证据/担保 | E12: 正常范围：与账龄、客户信用风险和政策一致；关注范围：部分账龄计提明显偏低；高风险范围：高风险/长期逾期应收仍维持明显偏低计提且无充分依据 | F12: 正常范围：回款与收入变化基本一致；关注范围：回款明显弱于收入增长；高风险范围：回款持续恶化而坏账准备未同步反映风险 | G12: 正常范围：变动能够勾稽；关注范围：单一环节无法解释；高风险范围：多个环节同时异常或存在虚增应收账款证据
A13: RAG_Keywords | B13: 应收账款 应收票据 应收款项 客户 贸易应收 账款 | C13: 营业收入 收入增长 销售收入 回款 经营活动现金流 销售商品收到的现金 | D13: 逾期 账龄 一年以上 三年以上 长期未收回 逾期应收账款 | E13: 坏账准备 信用减值损失 预期信用损失 计提比例 坏账率 单项计提 | F13: 回款 现金回款 经营活动现金流 收现比 应收账款回收 | G13: 坏账准备期初 坏账准备期末 核销 转销 信用减值损失 账龄迁徙
A14: Evidence_Required | B14: 财务数据+年报原文+应收账款账龄及坏账政策；重点取得不同账龄的计提比例。 | C14: 财务数据+现金流量表；关注应收账款快速增长但收入增长或现金回款没有同步增长的情况。 | D14: 应收账款账龄明细+客户回款信息；重点关注长期逾期、诉讼、经营困难客户。 | E14: 坏账准备政策+账龄结构；不能只比较一个总计提比例，应结合账龄和信用风险。 | F14: 现金流量表+应收账款附注；关注回款恶化与信用减值损失变化是否匹配。 | G14: 坏账准备变动表+信用减值损失+核销/转销；检查期初期末勾稽关系和账龄迁徙。
A15: 定性证据 | B15: 收入快速增长、季节性销售、重大客户集中、并购等可能导致应收账款阶段性增加，需要结合业务背景判断。 | C15: 应收账款增长快于收入并不必然异常，应结合信用政策、结算方式、销售季节性和客户结构解释。 | D15: 逾期比例高但客户信用良好、已有充分担保或期后快速回款，可以作为合理解释，但需要年报或外部证据支持。 | E15: 爱迪尔案例中，截至2019年末累计虚增应收账款42,860.11万元，2017—2019年分别虚增6,300.72万元、12,154.31万元、24,405.09万元，并对前述虚增应收账款不当计提坏账准备，2017—2021年分别导致利润总额虚减214.90万元、381.12万元、8,863.34万元、9,994.53万元、6,450.90万元。该案例支持“应收账款真实性+坏账计提”必须联动检查。 | F15: 同行业比较可以作为辅助证据，但不能仅因低于同行就认定计提不足；应优先核查公司自身账龄、历史回款和客户信用情况。 | G15: 如果发现应收账款真实性本身存在问题，应升级为“虚增应收账款/收入”相关风险，而不是只判断坏账计提比例。

Sheet R012
A1: 风险编号riskid | B1: R012
A2: 风险名称riskname | B2: 关联交易非关联化
A3: 风险类型Risk_Category | B3: 关联交易与资金占用类
A4: 定义解释Definition | B4: 把关联方伪装成第三方客户供应商，虚构业务，输送利益、虚增营收，隐瞒关联关系。
A5: 信号编号Signal ID | B5: R012-S01 | C5: R012-S02 | D5: R012-S03 | E5: R012-S04 | F5: R012-S05 | G5: R012-S06
A6: 信号名称Signal_Name | B6: 新增大额陌生第三方客户 / 供应商 | C6: 客户供应商与实控人 / 高管存在隐性关联关系 | D6: 对陌生第三方营收 / 采购占比异常偏高 | E6: 交易商业实质存疑，交易条款异常 | F6: 交易回款付款高度依赖关联方资金循环 | G6: 关联关系隐瞒，未在年报披露关联交易
A7: 信号类型Signal_Type | B7: 定量 + 定性 | C7: 定量 + 定性 | D7: 定量 | E7: 定量 + 定性 | F7: 定量 | G7: 定性
A8: 公式Formula | B8: 1.新增大客户营收占比 = 本期新增前五大客户营收 ÷ 全部营业收入 ×100% 2.新增大供应商采购占比 = 本期新增前五大供应商采购额 ÷ 营业成本 ×100% 3.新增大客户 / 供应商成立时间距离交易发生时间间隔 | C8: 1.隐性关联方交易规模占比 = 穿透识别的伪装关联方交易金额 ÷ 营业收入 ×100% 2.工商股权穿透重合度：董监高、实控人亲属对外投资企业与客户供应商重合情况 3.人员、办公地址、联系方式重合识别 | D8: 1.陌生第三方营收占比 = 来自陌生第三方客户营业收入 ÷ 总营业收入 ×100% 2.陌生第三方采购占比 = 来自陌生第三方供应商采购额 ÷ 总采购金额 ×100% 3.前五大客户中新增主体数量占比 4.单笔大额陌生客户销售占营收比重 | E8: 1.交易毛利率偏离度 =（该笔交易毛利率‑公司综合毛利率）÷ 公司综合毛利率 ×100% 2.账期偏离度 = 该客户账期‑公司常规客户平均账期 3.无合理商业理由的大额交易 | F8: 1.客户回款来自实控人及其关联方金额占比 = 该类回款金额 ÷ 对应客户应收账款回款总额 ×100% 2.供应商付款流向实控人关联方金额占比 = 该类付款金额 ÷ 对应供应商总付款金额 ×100% 3.资金闭环识别：客户回款‑供应商付款流向形成闭环 | G8: 1.穿透识别的关联交易，年报未列入关联交易板块 2.交易对手实际为关联方，但披露为独立第三方 3.交易所问询后才补披露关联关系
A14: 数据来源Data_Source | B14: 年报前五大客户、前五大供应商披露、营业收入明细、客户供应商工商信息、交易所问询函 | C14: 客户供应商工商档案、股权穿透、董监高及实控人亲属对外投资企业、企查查天眼查、问询函回复 | D14: 年报前五大客户供应商、利润表营业收入、营业成本、采购销售明细台账 | E14: 年报分产品毛利率、客户账龄明细、销售合同、采购合同、交易所监管函 | F14: 货币资金流水、银行回单、往来明细账、客户供应商银行账户信息、问询函资金流水核查回复 | G14: 年报关联交易附注、董事会报告、交易所问询函及回复、监管处罚公告
A15: 阈值Threshold | B15: 前五大新增陌生客户营收占比合计 >15% 触发关注；>30% 触发高风险。 • 前五大新增陌生供应商采购占比合计 >15% 触发关注；>30% 触发高风险。 • 成立当年即成为前五大客户/供应商 → 直接触发高风险 | C15: 隐性关联交易规模占营收 >5% 触发关注；>10% 触发高风险。 • 只要发现工商、人员、地址、电话重合即触发高风险 | D15: 陌生第三方营收占比＞30% 触发关注；陌生第三方采购占比＞30% 触发关注 | E15: 毛利率正向偏离 > +50%（即高于综合毛利率50%）触发关注（虚增营收嫌疑）；> +100% 触发高风险。 • 毛利率负向偏离 < -30%（即低于综合毛利率30%）触发关注（利益输送嫌疑）；< -50% 触发高风险。 • 账期偏离度建议增加绝对值阈值：“账期高于平均账期60天以上且无合理解释”触发关注。 | F15: 流向关联方占比 >20% 触发关注；>50% 触发高风险。 • 识别出资金闭环 → 直接触发高风险（保留）。 | G15: 穿透核查确认属于关联交易，但年报未披露，直接触发高风险；被交易所问询关联关系存疑触发关注
A16: RAG_Keywords | B16: 年报前五大客户、前五大供应商披露、营业收入明细、客户供应商工商信息、交易所问询函 | C16: 客户供应商工商档案、股权穿透、董监高及实控人亲属对外投资企业、企查查天眼查、问询函回复 | D16: 年报前五大客户供应商、利润表营业收入、营业成本、采购销售明细台账 | E16: 年报分产品毛利率、客户账龄明细、销售合同、采购合同、交易所监管函 | F16: 货币资金流水、银行回单、往来明细账、客户供应商银行账户信息、问询函资金流水核查回复 | G16: 年报关联交易附注、董事会报告、交易所问询函及回复、监管处罚公告
A17: Evidence_Required | B17: 财务数据+年报原文
A21: 备注：选取前五大客户，一是上市公司年报强制披露前五大客户数据，公开数据可获取；二是舞弊主体倾向于通过少数大额对手高效虚增营收，前五大客户对报表影响重大；同时正常企业核心大客户通常具备业务延续性，新闯入前五大的陌生客户具备较高舞弊嫌疑。缺陷是无法识别刻意控制在前五之外的虚假客户。

Sheet R013
A1: 风险编号riskid | C1: R013
A2: 风险名称riskname | C2: 大股东/实控人资金占用
A3: 风险类型Risk_Category | C3: 关联交易与资金占用类
A4: 定义解释Definition | C4: 上市公司资金通过预付款、其他应收款、贸易往来流向实控人及其体外公司；资金被挪用。
A5: 信号编号Signal ID | C5: R013-S01 | D5: RO13-S02 | E5: R013-S03 | F5: R013-S04 | G5: R013-S05 | H5: R013-S06
A6: 信号名称Signal_Name | C6: 预付款项异常增长 / 长期挂账； | D6: 其他应收款异常增长 / 大额挂账 | E6: 贸易往来异常（无商业实质的大额采购 / 销售） | F6: 货币资金与有息负债 "大存大贷" | G6: 实控人高比例质押 / 资金紧张（占用动机） | H6: 资金流向穿透后到达实控人或体外公司
A7: 信号类型Signal_Type | C7: 定量 | D7: 定量 | E7: 定量 + 定性 | F7: 定量 + 定性 | G7: 定量 | H7: 定性+定量
A8: 公式Formula | C8: 1.预付款项增长率 =（本期预付款项−上期预付款项）÷ 上期预付款项 × 100% 2.长账龄预付占比 = 账龄 1 年以上预付款项 ÷ 预付款项总额 × 100% | D8: 其他应收款占总资产比 = 其他应收款 ÷ 总资产 × 100% | E8: 贸易业务毛利率 =（贸易收入−贸易成本）÷ 贸易收入 × 100% | F8: 有息负债 / 货币资金 =（短期借款 + 长期借款 + 应付债券 + 一年内到期非流动负债）÷ 货币资金 | G8: 实控人股权质押比例 = 实控人已质押股份数 ÷ 实控人持股总数 × 100% | H8: 资金回流比率 = 流出后最终回流实控人 / 体外公司的资金额 ÷ 预付款及其他应收款新增总额 × 100%
A14: 数据来源Data_Source | C14: 资产负债表（预付款项）；年报附注：预付款项账龄明细、预付对象明细；现金流量表（购买商品支付的现金） | D14: 资产负债表（其他应收款、总资产）；年报附注：其他应收款账龄、欠款方明细、坏账准备 | E14: 利润表（营业收入、营业成本）；年报附注：分部业务、贸易业务披露；重大合同公告；工商对手信息 | F14: 资产负债表（货币资金、短期借款、长期借款、应付债券、一年内到期的非流动负债）；利润表（财务费用、利息收入）；年报附注：借款明细、货币资金受限说明 | G14: 年报附注「实际控制人、股东持股、股份质押冻结情况」，还有交易所披露的股权质押临时公告。 | H14: 资产负债表（预付款、其他应收款）、**银行流水（核心）**、工商信息（穿透对手是谁控制）、理财 / 私募基金投向公告。
A15: 阈值Threshold | C15: 预付款项增长率同比大幅飙升；长账龄预付占比＞30% 触发关注 | D15: 其他应收款占总资产＞5% 触发关注；同比大幅异常增加 | E15: 贸易业务毛利率趋近于 0（0‑2% 区间）触发关注；规模巨大但几乎不产生毛利 | F15: 有息负债远高于账面货币资金，利息收入显著低于活期存款合理收益，触发关注 | G15: 实控人股权质押比例＞70% 触发关注。 | H15: ＞30% 高度可疑
A16: RAG_Keywords | C16: 预付款项、预付账款、预付工程款、预付货款、账龄、长期挂账、大额预付 | D16: 其他应收款、往来款、其他非流动资产、资金拆借、备用金、欠款方、坏账 | E16: 贸易往来、空转贸易、大宗贸易、贸易业务、无商业实质、货物流转、虚构贸易 | F16: 大存大贷、存贷双高、货币资金、有息负债、短期借款、财务费用、利息收入、受限资金 | G16: 实际控制人、大股东、股权质押、股份冻结、高质押率、质押公告、资金紧张 | H16: 资金占用、非经营性资金占用、体外公司、资金回流、资金闭环、资金挪用、资金流向
A17: Evidence_Required

Sheet R014
A1: 风险编号riskid | C1: R014
A2: 风险名称riskname | C2: 违规担保
A3: 风险类型Risk_Category | C3: 关联交易与资金占用类
A4: 定义解释Definition | C4: 上市公司未经董事会、股东大会审议程序，擅自为实际控制人、大股东及其关联方债务提供担保、反担保，且不在年报对外担保附注中如实披露，形成表外隐性负债，一旦债务人违约，上市公司承担连带清偿责任，损害中小股东利益。
A5: 信号编号Signal ID | C5: R014‑S01 | D5: R014-S02 | E5: R014-S03 | F5: R014-S04 | G5: R014-S05
A6: 信号名称Signal_Name | C6: 担保未履行审议程序 | D6: 年报担保披露不完整 / 未披露 | E6: 或有负债 / 预计负债异常 | F6: 诉讼仲裁公告暴露隐性担保 | G6: 实控人高负债 / 高质押（担保动机）
A7: 信号类型Signal_Type | C7: 定量 + 定性 | D7: 定性 | E7: 定量 | F7: 定量 + 定性 | G7: 定量
A8: 公式Formula | C8: 1.未审议担保占净资产比 = 未经董事会 / 股东大会审议的担保金额 ÷ 归属于上市公司股东的净资产 × 100% 2.担保总额占净资产比 = 对外担保总额 ÷ 归属于上市公司股东的净资产 × 100% | D8: 1. 年报 "或有事项" 附注中对外担保明细缺失或金额明显偏低 2. 已通过诉讼、仲裁、代偿公告暴露的担保，年报中未对应披露 3. 担保对象为实控人、大股东及其关联方，但未列入关联交易披露 4. 交易所问询函追问担保情况，公司回复含糊或前后矛盾 | E8: 1.预计负债占担保总额比 = 计提的预计负债 ÷ 对外担保总额 × 100% 2.担保覆盖率 = 已计提预计负债 ÷ 涉诉担保金额 × 100% | F8: 涉诉担保金额占净资产比 = 因担保被起诉 / 仲裁涉及的金额 ÷ 归属于上市公司股东的净资产 × 100% | G8: 1.实控人股权质押比例 = 实控人已质押股份数 ÷ 实控人持股总数 × 100% 2.实控人及关联方有息负债规模（如可获取）
A14: 数据来源Data_Source | C14: 年报附注（对外担保明细、董事会决议公告、股东大会决议公告）、公司公告（担保公告）、交易所问询函 | D14: 年报附注（或有事项、对外担保、关联交易）、诉讼公告、仲裁公告、交易所问询函及回复 | E14: 资产负债表（预计负债、其他应付款）、年报附注（预计负债明细、或有事项）、利润表（营业外支出） | F14: 公司公告（重大诉讼公告、仲裁公告）、年报附注（重大诉讼仲裁）、裁判文书网、交易所监管函 | G14: 年报附注（实际控制人持股及质押情况）、股权质押公告、实控人控制企业的工商及债务信息
A15: 阈值Threshold | C15: 担保总额占净资产＞50% 触发关注；存在未经审议的担保即触发高风险 | D15: 存在已暴露但年报未披露的担保即触发高风险 | E15: 存在大额担保但未计提预计负债（预计负债占担保总额≈0）触发关注；担保代偿后营业外支出异常增加 | F15: 涉诉担保金额占净资产＞10% 触发关注；单笔担保涉诉金额＞5000 万触发关注 | G15: 实控人股权质押比例＞70% 触发关注；实控人存在债务违约 / 被执行记录触发高风险
A16: RAG_Keywords | C16: 对外担保、担保总额、担保余额、董事会审议、股东大会审议、审议程序、担保公告、连带责任担保、反担保 | D16: 或有事项、对外担保、未披露担保、隐瞒担保、担保明细、担保对象、关联方担保、或有负债 | E16: 预计负债、或有负债、营业外支出、担保代偿、连带责任、未决诉讼、未决仲裁、计提 | F16: 重大诉讼、仲裁、起诉、被诉、连带清偿责任、担保纠纷、裁判文书、监管函、警示函 | G16: 实际控制人、股权质押、股份冻结、债务违约、被执行人、失信被执行人、资金链、高负债
A17: Evidence_Required

Sheet R015
A1: 风险编号riskid | C1: R015
A2: 风险名称riskname | C2: 隐瞒负债、少记预计负债
A3: 风险类型Risk_Category | C3: 负债、会计估计、信息披露舞弊
A4: 定义解释Definition | C4: 上市公司对已经发生的诉讼赔偿、违约义务、担保代偿等现时义务，不按照《企业会计准则第 13 号 —— 或有事项》确认预计负债，或少计预计负债金额，隐瞒表内负债，低估负债规模，虚增当期利润。表现为重大诉讼已公告但报表无预计负债、债务已违约但不确认损失、表外隐性负债不入账等
A5: 信号编号Signal ID | C5: R015-S01 | D5: R015-S02 | E5: R015-S03 | F5: R015-S04 | G5: R015-S05 | H5: R015-S06
A6: 信号名称Signal_Name | C6: 重大诉讼 / 仲裁未计提预计负债 | D6: 违约义务 / 债务逾期未确认预计负债 | E6: 预计负债计提金额显著不足 | F6: 表外负债 / 隐性担保不入账 | G6: 预计负债与营业外支出勾稽异常 | H6: 后续实际赔偿 / 违约支出远超计提数
A7: 信号类型Signal_Type | C7: 定量 + 定性 | D7: 定量 + 定性 | E7: 定量 | F7: 定量 + 定性 | G7: 定量 | H7: 定量
A8: 公式Formula | C8: 1.预计负债占涉诉金额比 = 账面计提预计负债 ÷ 重大诉讼涉诉总金额 × 100% 2.涉诉金额占净资产比 = 重大诉讼涉诉总金额 ÷ 归属于上市公司股东净资产 × 100% | D8: 1.违约债务占总有息负债比 = 已违约 / 逾期有息负债 ÷ 总有息负债 × 100% 2.逾期未确认损失金额 = 已违约债务应确认损失 − 账面已确认损失 | E8: 1.预计负债充足率 = 已计提预计负债 ÷ 按准则应计提预计负债 × 100% 2.预计负债占总负债比 = 预计负债 ÷ 总负债 × 100% | F8: 1.表外负债估算占比 = 穿透识别出的表外负债 ÷ 账面总负债 × 100% 2.明股实债、抽屉协议、隐性担保识别 | G8: 1.勾稽差额 = 期初预计负债 + 本期计提 − 本期冲回 − 本期实际支付 − 期末预计负债 2.营业外支出异常增长率 =（本期营业外支出 − 上期营业外支出）÷ 上期营业外支出 × 100% | H8: 1.实际赔偿超计提比率 =（实际赔偿金额 − 已计提预计负债）÷ 已计提预计负债 × 100% 2.期后赔偿占比 = 资产负债表日后实际赔偿金额 ÷ 期末预计负债余额 × 100%
A14: 数据来源Data_Source | C14: 资产负债表（预计负债）、年报附注（预计负债、或有事项、重大诉讼仲裁）、重大诉讼公告、裁判文书网、交易所问询函 | D14: 资产负债表（短期借款、长期借款、应付债券、一年内到期非流动负债）、年报附注（借款明细、违约情况）、债务违约公告、评级报告 | E14: 资产负债表（预计负债、总负债）、年报附注（预计负债明细、或有事项）、利润表（营业外支出）、同行业可比公司预计负债计提比例 | F14: 年报附注（或有事项、对外担保、关联交易）、资产负债表（其他权益工具、长期应付款）、工商穿透、抽屉协议、明股实债合同 | G14: 资产负债表（预计负债）、利润表（营业外支出）、年报附注（预计负债变动表、营业外支出明细） | H14: 资产负债表日后事项公告、实际赔偿支付凭证、年报附注（期后事项、预计负债）、利润表（营业外支出）
A15: 阈值Threshold | C15: 发布重大诉讼公告但账面预计负债为 0 即触发高风险；预计负债占涉诉金额比＜30% 触发关注；涉诉金额占净资产＞10% 触发关注 | D15: 存在债务违约但未确认预计负债即触发高风险；违约债务占总有息负债＞5% 触发关注 | E15: 预计负债充足率＜50% 触发关注；预计负债占总负债比显著低于同行业触发关注 | F15: 存在表外负债 / 隐性担保即触发高风险；表外负债估算占比＞10% 属重大风险 | G15: 勾稽差额≠0 且无法解释触发关注；营业外支出异常增长率＞50% 触发关注 | H15: 实际赔偿超计提比率＞50% 触发关注；期后赔偿占比＞100%（即赔偿额超过计提数）触发高风险
A16: RAG_Keywords | C16: 预计负债、或有事项、重大诉讼、仲裁、未决诉讼、涉诉金额、诉讼赔偿、判决、败诉、连带责任 | D16: 债务违约、逾期借款、债券违约、违约义务、信用违约、交叉违约、债务重组、无法偿付 | E16: 预计负债、计提比例、计提不足、少计负债、或有负债、负债规模、同行业对比、会计估计 | F16: 表外负债、隐性担保、明股实债、抽屉协议、或有负债、未入账负债、隐性债务、担保余额 | G16: 预计负债变动、营业外支出、勾稽关系、计提冲回、实际支付、赔偿支出、损失确认 | H16: 期后事项、实际赔偿、赔偿支出、超预计赔偿、期后调整、以前年度损益调整、营业外支出

Sheet R016
A1: 风险编号riskid | C1: R016
A2: 风险名称riskname | C2: 滥用会计估计
A3: 风险类型Risk_Category | C3: 负债、会计估计、信息披露舞弊
A4: 定义解释Definition | C4: 上市公司随意变更固定资产折旧年限 / 方法、坏账准备计提比例、存货跌价计提比例、商誉减值测试参数等会计估计，变更理由不基于业务实质，而是以调节利润为目的，通过少计折旧、少提坏账准备等方式虚增利润，甚至直接实现扭亏为盈。变更往往未充分披露理由和影响，或披露理由与实际经营情况不符。
A5: 信号编号Signal ID | C5: R016-S01 | D5: R016-S02 | E5: R016-S03 | F5: R016-S04 | G5: R016-S05 | H5: R016-S06
A6: 信号名称Signal_Name | C6: 折旧年限 / 方法随意变更 | D6: 坏账计提比例随意变更 | E6: 会计估计变更后直接扭亏为盈 | F6: 会计估计变更缺乏合理依据 / 未充分披露 | G6: 折旧 / 坏账计提比例显著偏离同行业 | H6: 会计估计变更频繁 / 反复变更
A7: 信号类型Signal_Type | C7: 定量 | D7: 定量 | E7: 定量 | F7: 定性 | G7: 定量 | H7: 定量 + 定性
A8: 公式Formula | C8: 1.折旧年限变更幅度 =（新折旧年限 − 旧折旧年限）÷ 旧折旧年限 × 100% 2.折旧政策变更对利润影响额 = 按旧政策应计折旧额 − 按新政策实际折旧额 3.综合折旧率 = 本期折旧费用 ÷ 固定资产平均原值 × 100% | D8: 1.坏账计提比例变更幅度 =（新计提比例 − 旧计提比例）÷ 旧计提比例 × 100% 2.坏账政策变更对利润影响额 = 按旧比例应提坏账 − 按新比例实际计提坏账 3.综合坏账率 = 期末坏账准备 ÷ 期末应收账款余额 × 100% | E8: 1.会计估计变更影响利润占比 = 会计估计变更增加的净利润 ÷ 变更后净利润 × 100% 2.变更前后盈亏性质 = 变更前净利润（负）→ 变更后净利润（正） 3.扣非后净利润是否仍为正（剔除估计变更影响） | F8: 1. 是否披露变更理由、变更日期、影响金额 2. 变更理由是否与实际经营情况一致 .3. 影响金额是否量化披露 | G8: 1.综合折旧率偏离度 =（公司综合折旧率 − 同行业平均综合折旧率）÷ 同行业平均综合折旧率 × 100% 2.综合坏账率偏离度 =（公司综合坏账率 − 同行业平均综合坏账率）÷ 同行业平均综合坏账率 × 100% | H8: 1.会计估计变更频率 = 报告期内会计估计变更次数 2.同一估计项目反复变更次数 = 近 3 年同一项目变更次数 4.【定性】变更方向是否始终指向增加利润
A14: 数据来源Data_Source | C14: 资产负债表（固定资产、累计折旧）、年报附注（固定资产折旧政策、会计估计变更公告）、利润表（管理费用 / 制造费用中折旧） | D14: 资产负债表（应收账款、坏账准备）、年报附注（坏账准备政策、账龄分析、会计估计变更公告）、利润表（信用减值损失） | E14: 利润表（净利润、扣非净利润）、年报附注（会计估计变更对利润影响说明）、会计估计变更公告 | F14: 年报附注（会计估计变更披露段）、会计估计变更公告、交易所问询函及回复、董事会 / 股东大会决议 | G14: 年报附注（折旧政策、坏账政策、存货跌价政策）、同行业可比公司年报、行业平均数据 | H14: 历年年报附注（会计政策与会计估计变更段）、会计估计变更公告、交易所问询函
